Workbook

Sheet ValueType
A1: Integer
A2: Float
A3: String
A4: Bytes
A5: IntegerVec
A6: FloatVec

Sheet ChangeMode
A1: OnChange
A2: Continuous
A3: Event

Sheet Domain
A1: Internal
A2: Vehicle
A3: MCU
A4: IVI
A5: PSIS
A6: ADAS

Sheet Readme
B2: ****表格结构禁止修改，否则无法生成配置文件与头文件**** *文档中禁止出现空行* sheet 命名规则 格式：domain.group 例子：vehicle.rx 表头说明： 【属性名】 1. 大写+下划线，例如：MY_PROP，USR_CFG_PROP，D008，SIGNAL_1 2. 尽量与SRD中描述的can信号命名保持一致 ,如SRD中的信号名称过于简化无法表示功能作用，需要自己另行定义 3. 如需填写时要保证在所属sheet页中的唯一性，禁止为空 【读写模式】 1.*必须使用下拉框填写，禁止手动填写，禁止为空 2. read 只读属性，只允许监听和获取值 3. read&write 可读写属性，可允许设置属性值 【通知模式】 1.*必须使用下拉框填写，禁止手动填写，禁止为空 2. OnEvent，针对一个属性的值的写入，必然会触发属性值回调； 3. OnChange，针对一个属性的值的写入，只有与上一次写入的值不同才会触发属性值回调； 4. ContinuousOnChange，需要指定一个采样频率，按此频率轮训属性值，只有与上一次的值不同才会触发； 【通知周期】 1. 整数值，单位ms 2. 当“通知模式”是ContinuousOnChange时有效，即轮训间隔； 【属性值类型】 1.*必须使用下拉框填写，禁止手动填写 ，禁止为空 2. array, 数组形式，每个元素都可以且仅可以是属性值类型中的一种，array的自身嵌套待定 3. map, 带有键值的属性值, 每个元素对均带有一个字符串形式的键值key(first)，另外一个类型的属性值(second)，map的自身嵌套待定 【默认值】 1.*禁止为空 2. 默认值 未向属性设置值之前 一直保持该值。注：处于默认值的属性，在被订阅时，不会收到即时的值通知 3. 一般情况下默认值需要来自SRD定义 4 .默认值类型必须与 value_type 对应 【属性意义】 1.注释，要求描述清晰，能在不在其他文档辅助的情况下清晰明确该属性的作用 2.可使用中文描述， 【属性值长度 - psis.usr_cfg 特化】 1.必填

Sheet statistic
A1: 进程名全称 | B1: 进程名缩写 | C1: Modules | D1: HOST | E1: COUNT | F1: psis.car_cfg | G1: psis.usr_cfg | H1: vehicle.rx | I1: vehicle.tx | J1: ivi.rx | K1: ivi.tx | L1: custom.mcu | M1: custom.drivinginfo | N1: custom.telltale | O1: custom.warning | P1: custom.power | Q1: custom.apa | R1: custom.hmi | S1: custom.hardkey | T1: someip.rx | U1: custom.avm | V1: custom.dms | W1: vehicle.rxH | X1: adas.rx | Y1: vehicle_n8.rx
A2: animation_midware | B2: ANI | C2: AnimModule | D2: 0 | E2: =F2*F18+G2*G18+H2*H18+I2*I18+J2*J18+K2*K18+L2*L18+M2*M18+N2*N18+O2*O18+P2*P18+Q2*Q18+R2*R18+S2*S18+T2*T18+U2*U18+V2*V18+W2*W18+X2*X18+Y2*Y18 | F2: 0 | G2: 1 | H2: 1 | I2: 0 | J2: 1 | K2: 0 | L2: 0 | M2: 0 | N2: 0 | O2: 0 | P2: 1 | Q2: 0 | R2: 0 | S2: 0 | T2: 0 | U2: 0 | V2: 0 | W2: 0 | X2: 0 | Y2: 0
A3: avm_midware | B3: AVMM | C3: AvmModule | D3: 0 | E3: =F3*F18+G3*G18+H3*H18+I3*I18+J3*J18+K3*K18+L3*L18+M3*M18+N3*N18+O3*O18+P3*P18+Q3*Q18+R3*R18+S3*S18+T3*T18+U3*U18+V3*V18+W3*W18+X3*X18+Y3*Y18 | F3: 1 | G3: 0 | H3: 1 | I3: 1 | J3: 0 | K3: 1 | L3: 1 | M3: 0 | N3: 0 | O3: 0 | P3: 1 | Q3: 1 | R3: 0 | S3: 0 | T3: 1 | U3: 0 | V3: 0 | W3: 0 | X3: 0 | Y3: 0
A4: cluster_early_midware | B4: CEM | C4: SccComModule PowerModule TellTaleModule AvasModule | D4: 1 | E4: =F4*F18+G4*G18+H4*H18+I4*I18+J4*J18+K4*K18+L4*L18+M4*M18+N4*N18+O4*O18+P4*P18+Q4*Q18+R4*R18+S4*S18+T4*T18+U4*U18+V4*V18+W4*W18+X4*X18+Y4*Y18 | F4: 1 | G4: 1 | H4: 1 | I4: 1 | J4: 1 | K4: 1 | L4: 1 | M4: 1 | N4: 1 | O4: 1 | P4: 1 | Q4: 0 | R4: 1 | S4: 0 | T4: 1 | U4: 0 | V4: 1 | W4: 1 | X4: 1 | Y4: 1
A5: cluster_midware | B5: CM | C5: WarnModule DrivingInfoModule KeyModule ChimeModule HMIStateModule SettingsModule | D5: 0 | E5: =F5*F18+G5*G18+H5*H18+I5*I18+J5*J18+K5*K18+L5*L18+M5*M18+N5*N18+O5*O18+P5*P18+Q5*Q18+R5*R18+S5*S18+T5*T18+U5*U18+V5*V18+W5*W18+X5*X18+Y5*Y18 | F5: 1 | G5: 1 | H5: 1 | I5: 1 | J5: 1 | K5: 1 | L5: 1 | M5: 1 | N5: 1 | O5: 1 | P5: 1 | Q5: 0 | R5: 1 | S5: 1 | T5: 1 | U5: 0 | V5: 1 | W5: 1 | X5: 1 | Y5: 1
A6: diag_midware | B6: DIAG | C6: Diagnosis | D6: 0 | E6: =F6*F18+G6*G18+H6*H18+I6*I18+J6*J18+K6*K18+L6*L18+M6*M18+N6*N18+O6*O18+P6*P18+Q6*Q18+R6*R18+S6*S18+T6*T18+U6*U18+V6*V18+W6*W18+X6*X18+Y6*Y18 | F6: 1 | G6: 1 | H6: 1 | I6: 1 | J6: 1 | K6: 1 | L6: 1 | M6: 0 | N6: 0 | O6: 0 | P6: 0 | Q6: 0 | R6: 0 | S6: 0 | T6: 1 | U6: 0 | V6: 0 | W6: 0 | X6: 0 | Y6: 0
A7: dms_midware | B7: DMS | C7: DmsModule | D7: 0 | E7: =F7*F18+G7*G18+H7*H18+I7*I18+J7*J18+K7*K18+L7*L18+M7*M18+N7*N18+O7*O18+P7*P18+Q7*Q18+R7*R18+S7*S18+T7*T18+U7*U18+V7*V18+W7*W18+X7*X18+Y7*Y18 | F7: 1 | G7: 1 | H7: 1 | I7: 1 | J7: 1 | K7: 1 | L7: 1 | M7: 0 | N7: 0 | O7: 0 | P7: 1 | Q7: 0 | R7: 0 | S7: 0 | T7: 0 | U7: 0 | V7: 1 | W7: 0 | X7: 0 | Y7: 1
A8: drm_midware | B8: DRM | C8: DrmModule | D8: 0 | E8: =F8*F18+G8*G18+H8*H18+I8*I18+J8*J18+K8*K18+L8*L18+M8*M18+N8*N18+O8*O18+P8*P18+Q8*Q18+R8*R18+S8*S18+T8*T18+U8*U18+V8*V18+W8*W18+X8*X18+Y8*Y18 | F8: 0 | G8: 0 | H8: 0 | I8: 0 | J8: 1 | K8: 1 | L8: 0 | M8: 1 | N8: 0 | O8: 0 | P8: 1 | Q8: 0 | R8: 0 | S8: 0 | T8: 0 | U8: 0 | V8: 0 | W8: 0 | X8: 0 | Y8: 0
A9: oms_midware | B9: OMS | C9: OmsModule | D9: 0 | E9: =F9*F18+G9*G18+H9*H18+I9*I18+J9*J18+K9*K18+L9*L18+M9*M18+N9*N18+O9*O18+P9*P18+Q9*Q18+R9*R18+S9*S18+T9*T18+U9*U18+V9*V18+W9*W18+X9*X18+Y9*Y18 | F9: 0 | G9: 0 | H9: 0 | I9: 0 | J9: 1 | K9: 1 | L9: 0 | M9: 0 | N9: 0 | O9: 0 | P9: 1 | Q9: 0 | R9: 0 | S9: 0 | T9: 0 | U9: 0 | V9: 1 | W9: 0 | X9: 0 | Y9: 0
A10: cluster-hmi | B10: HMI | D10: 0 | E10: =F10*F18+G10*G18+H10*H18+I10*I18+J10*J18+K10*K18+L10*L18+M10*M18+N10*N18+O10*O18+P10*P18+Q10*Q18+R10*R18+S10*S18+T10*T18+U10*U18+V10*V18+W10*W18+X10*X18+Y10*Y18 | F10: 1 | G10: 1 | H10: 0 | I10: 0 | J10: 1 | K10: 1 | L10: 1 | M10: 1 | N10: 1 | O10: 1 | P10: 1 | Q10: 0 | R10: 1 | S10: 0 | T10: 0 | U10: 0 | V10: 1 | W10: 0 | X10: 0 | Y10: 0
A11: EarlyTT | B11: TT | D11: 0 | E11: =F11*F18+G11*G18+H11*H18+I11*I18+J11*J18+K11*K18+L11*L18+M11*M18+N11*N18+O11*O18+P11*P18+Q11*Q18+R11*R18+S11*S18+T11*T18+U11*U18+V11*V18+W11*W18+X11*X18+Y11*Y18 | F11: 0 | G11: 1 | H11: 0 | I11: 0 | J11: 1 | K11: 0 | L11: 0 | M11: 1 | N11: 1 | O11: 0 | P11: 1 | Q11: 0 | R11: 1 | S11: 0 | T11: 0 | U11: 0 | V11: 0 | W11: 0 | X11: 0 | Y11: 0
A12: avm-hmi | B12: AVMH | D12: 0 | E12: =F12*F18+G12*G18+H12*H18+I12*I18+J12*J18+K12*K18+L12*L18+M12*M18+N12*N18+O12*O18+P12*P18+Q12*Q18+R12*R18+S12*S18+T12*T18+U12*U18+V12*V18+W12*W18+X12*X18+Y12*Y18 | F12: 0 | G12: 0 | H12: 0 | I12: 0 | J12: 1 | K12: 0 | L12: 0 | M12: 0 | N12: 0 | O12: 0 | P12: 1 | Q12: 1 | R12: 0 | S12: 0 | T12: 0 | U12: 1 | V12: 0 | W12: 0 | X12: 0 | Y12: 0
A13: CarPropertyDbgr | B13: DBG | D13: 0 | E13: =F13*F18+G13*G18+H13*H18+I13*I18+J13*J18+K13*K18+L13*L18+M13*M18+N13*N18+O13*O18+P13*P18+Q13*Q18+R13*R18+S13*S18+T13*T18+U13*U18+V13*V18+W13*W18+X13*X18++Y13*Y18 | F13: 1 | G13: 1 | H13: 1 | I13: 1 | J13: 1 | K13: 1 | L13: 1 | M13: 1 | N13: 1 | O13: 1 | P13: 1 | Q13: 1 | R13: 1 | S13: 1 | T13: 1 | U13: 1 | V13: 1 | W13: 1 | X13: 1 | Y13: 1
A14: rtk_server | B14: RTKS | D14: 0 | E14: =F14*F18+G14*G18+H14*H18+I14*I18+J14*J18+K14*K18+L14*L18+M14*M18+N14*N18+O14*O18+P14*P18+Q14*Q18+R14*R18+S14*S18+T14*T18+U14*U18+V14*V18+W14*W18+X14*X18+Y14*Y18 | F14: 0 | G14: 1 | H14: 0 | I14: 0 | J14: 0 | K14: 0 | L14: 0 | M14: 0 | N14: 0 | O14: 0 | P14: 0 | Q14: 0 | R14: 0 | S14: 0 | T14: 0 | U14: 0 | V14: 0 | W14: 0 | X14: 0 | Y14: 0
A15: facreset_midware | B15: FACRESET | D15: 0 | E15: =F15*F18+G15*G18+H15*H18+I15*I18+J15*J18+K15*K18+L15*L18+M15*M18+N15*N18+O15*O18+P15*P18+Q15*Q18+R15*R18+S15*S18+T15*T18+U15*U18+V15*V18+W15*W18+X15*X18+Y15*Y18 | F15: 0 | G15: 0 | H15: 0 | I15: 0 | J15: 1 | K15: 0 | L15: 0 | M15: 0 | N15: 0 | O15: 0 | P15: 0 | Q15: 0 | R15: 0 | S15: 0 | T15: 0 | U15: 0 | V15: 0 | W15: 0 | X15: 0 | Y15: 0
A16: avas_midware | B16: AVAS | C16: AvasModule | D16: 0 | E16: =F16*F18+G16*G18+H16*H18+I16*I18+J16*J18+K16*K18+L16*L18+M16*M18+N16*N18+O16*O18+P16*P18+Q16*Q18+R16*R18+S16*S18+T16*T18+U16*U18+V16*V18+W16*W18+X16*X18+Y16*Y18 | F16: 1 | G16: 1 | H16: 1 | I16: 0 | J16: 1 | K16: 0 | L16: 1 | M16: 0 | N16: 0 | O16: 0 | P16: 1 | Q16: 0 | R16: 0 | S16: 0 | T16: 0 | U16: 0 | V16: 0 | W16: 0 | X16: 0 | Y16: 0
A18: 统计： | F18: =COUNTA('psis.car_cfg'!A2:A197) | G18: =COUNTA('psis.usr_cfg'!A2:A531) | H18: =COUNTA('vehicle.rx'!A2:A822) | I18: =COUNTA('vehicle.tx'!A2:A700) | J18: =COUNTA('ivi.rx'!A2:A843) | K18: =COUNTA('ivi.tx'!A2:A894) | L18: =COUNTA('custom.mcu'!A2:A495) | M18: =COUNTA('custom.drivinginfo'!A264:A922) | N18: =COUNTA('custom.telltale'!A2:A682) | O18: =COUNTA('custom.warning'!A2:A707) | P18: =COUNTA('custom.power'!A2:A695) | Q18: =COUNTA('custom.apa'!A2:A538) | R18: =COUNTA('custom.hmi'!A2:A709) | S18: =COUNTA('custom.hardkey'!A2:A511) | T18: =COUNTA('someip.rx'!A2:A701) | U18: =COUNTA('custom.avm'!A2:A527) | V18: =COUNTA('custom.dms'!A2:A506) | W18: =COUNTA('vehicle.rxH'!A2:A448) | X18: =COUNTA('adas.rx'!B2:B448) | Y18: =COUNTA('vehicle_n8.rx'!B2:B413)

Sheet ChangeHistory
B1: edit_time | C1: owner | D1: WarnDisplay
B2: 45756 | C2: 蔡鑫杰 | D2: 移植D01 CarPropertyList，删除大部分property
B3: 45762 | C3: 刘延琦 | D3: Vehicle.rx添加初版tt灯信号列表
B4: 45762 | C4: 邱煜凯 | D4: Vehicle.rx添加初版FixedDisplay信号列表
B5: 45762 | C5: 刘金岭 | D5: Vehicle.rx添加初版Warning信号列表
B6: 45762 | C6: 刘延琦 | D6: custom.telltale添加初版外发信号
B7: 45762 | C7: 刘金岭 | D7: custom.warning添加初版Warning信号
B8: 45762 | C8: 邱煜凯 | D8: custom.drivinginfo添加初版外发信号
B9: 45763 | C9: 蔡鑫杰 | D9: vehicle.rx增加整车电源模式信号
B10: 45764 | C10: 邱煜凯 | D10: custom.mcu添加初版外发信号
B11: 45765 | C11: 邱煜凯 | D11: 需求文档信号名称改动，Vehicle.rx初版FixedDisplay信号同步改动
B12: 45770 | C12: 华磊 | D12: 针对515节点，vehicle.rx新增档位信号有效位、车速、胎压、胎温、续驶里程等属性
B13: 45770 | C13: 邱煜凯 | D13: custom.mcu添加续驶里程(纯电)、续驶里程显示类型确认(纯电)、驱动功率限值百分比、能量回馈功率限值百分比信号
... B94: 45852 | C94: 邱煜凯 | D94: custom.drivinginfo 的 CHRGDCHAPWRDISP接口描述修改
B95: 2025/14 | C95: 蔡鑫杰 | D95: 【ivi.rx】增加N80的导航和通话状态
B96: 45852 | C96: 华磊 | D96: 根据配置字v2.8版，更新psis.car_cfg
B97: 45853 | C97: 刘金岭 | D97: vehicle.rx 添加融合dbc信号 VCU_ABNORCHARGPORTALERT_330
B98: 45853 | C98: 刘延琦 | D98: vehicle.rx添加DBC融合信号 VCU_ONEPEDALKEEPDISPLAY_AB_AS_358 PDCUEVST_AS_3B8 删除原有信号VCU_ONEPEDALKEEPDISPLAY_F03_358 VCU_ONEPEDALKEEPDISPLAY_358 PDCUEVST_3B5
B99: 45853 | C99: 刘延琦 | D99: vehicle.rx新增刹车信号与倒车信号BCM_BRKLAMPOUTPCMD_335 BCM_RVSLAMPOUTPCMD_335
B100: 45853 | C100: 刘金岭 | D100: vehicle.rx z新增dbc 融合 VCU_PARKING_REMIND_PGEAR_AB_AS_3B8 PDCUENRGMODFLTHINT_AS_3B8 PDCUENGSYSTWARN_AS_3B8
B101: 45853 | C101: 邱煜凯 | D101: vehicle.rx 新增dbc 融合 PDCUREFSWITCHSTS_AS_3B8
B102: 45853 | C102: 刘延琦 | D102: custom.telltale新增刹车灯 倒车灯状态信号TT_BRKLAMP_STS， TT_RVSLAMP_STS
B103: 45853 | C103: 刘金岭 | D103: ivi.rx I2C_SMART_TRUNK_SWITCH 更名为 I2C_SMART_KEY_SWITCH
B104: 45853 | C104: 谢天天 | D104: vehicle.rx新增PDCUBMSTEMPLOWDRVLIMITHINT_3D0
B105: 45855 | C105: 蔡鑫杰 | D105: costom.power 添加 STR 相关 property
B106: 45856 | C106: 刘延琦 | D106: custom.telltale修改REFUE_NOTICE_LIGHT的外发值
B107: 45856 | C107: 刘延琦 | D107: vehicle.rx添加传感器故障信号FAILRFUSAMPLECIRC_610
... B268: 46111 | C268: 刘延琦 | D268: vehicle_n8.rx 新增 PDCUHYDMILSTS_3D0

Sheet adas.rx
A1: 属性名 | B1: 读写模式 | C1: 通知模式 | D1: 通知周期 | E1: 属性值类型 | F1: 默认值 | G1: 属性意义 | H1: 备注 | I1: 适用车型
A2: ADAS_SYS_FAILED_INFO | B2: read | C2: OnChange | E2: int32 | F2: 0 | G2: 0no failed 1failed | H2: ADAS系统是否故障指示灯 | I2: N5 & N8
A3: ADAS_FCW_STATUS_INFO | B3: read | C3: OnChange | E3: int32 | F3: 0 | G3: 0OFF 1STANDBY 2READY 3ACTIVE 4ERROR | H3: FCW状态指示灯 | I3: N5 & N8
A4: ADAS_AEB_STATUS_INFO | B4: read | C4: OnChange | E4: int32 | F4: 0 | G4: 0OFF 1STANDBY 2READY 3ACTIVE 4ERROR | H4: AEB状态指示灯 | I4: N5 & N8
A5: ADAS_RDA_RCTA_STATUS_INFO | B5: read | C5: OnChange | E5: int32 | F5: 0 | G5: 0OFF 1STANDBY 2READY 3ACTIVE 4ERROR | H5: RCTA功能故障指示灯 | I5: N5 & N8
A6: ADAS_RDA_RCTB_STATUS_INFO | B6: read | C6: OnChange | E6: int32 | F6: 0 | G6: 0OFF 1STANDBY 2READY 3ACTIVE 4ERROR | H6: RCTB功能故障指示灯 | I6: N5 & N8
A7: ADAS_RDA_BSD_STATUS_INFO | B7: read | C7: OnChange | E7: int32 | F7: 0 | G7: 0OFF 1STANDBY 2READY 3ACTIVE 4ERROR | H7: BSD功能故障指示灯 | I7: N5 & N8
A8: ADAS_RDA_BSD_WRNGLEVEL_INFO | B8: read | C8: OnChange | E8: int32 | F8: 0 | G8: 0No_ACTION 1WARNING_LEVEL1, 2WARNING_LEVEL2, 3WARNING_LEVEL3, 4WARNING_LEVEL4, | H8: BSD功能报警等级 | I8: N5 & N8
A9: ADAS_RDA_LCA_STATUS_INFO | B9: read | C9: OnChange | E9: int32 | F9: 0 | G9: 0OFF 1STANDBY 2READY 3ACTIVE 4ERROR | H9: LCA功能故障指示灯 | I9: N5 & N8
A10: ADAS_RDA_LCA_WRNGLEVEL_INFO | B10: read | C10: OnChange | E10: int32 | F10: 0 | G10: 0No_ACTION 1WARNING_LEVEL1, 2WARNING_LEVEL2, 3WARNING_LEVEL3, 4WARNING_LEVEL4, | H10: LCA功能报警等级 | I10: N5 & N8
A11: ADAS_RDA_DOW_STATUS_INFO | B11: read | C11: OnChange | E11: int32 | F11: 0 | G11: 0OFF 1STANDBY 2READY 3ACTIVE 4ERROR | H11: DOW功能故障指示灯 | I11: N5 & N8
A12: ADAS_RDA_DOW_WRNGLEVEL_INFO | B12: read | C12: OnChange | E12: int32 | F12: 0 | G12: 0No_ACTION 1WARNING_LEVEL1, 2WARNING_LEVEL2, 3WARNING_LEVEL3, 4WARNING_LEVEL4, | H12: DOW功能报警等级 | I12: N5 & N8
A13: ADAS_RDA_RCW_STATUS_INFO | B13: read | C13: OnChange | E13: int32 | F13: 0 | G13: 0OFF 1STANDBY 2READY 3ACTIVE 4ERROR | H13: RCW功能故障指示灯 | I13: N5 & N8
... A43: ADAS_BSD_LCA_DIRECTION_RIGHT | B43: read | C43: OnChange | E43: int32 | F43: 0 | G43: BSD/LCA功能报警方向信号-右侧报警 0未报警 1右报警 | H43: BSD/LCA 3D音效 | I43: N8

Sheet custom.drivinginfo
A1: 属性名 | B1: 读写模式 | C1: 通知模式 | D1: 通知周期 | E1: 属性值类型 | F1: 默认值 | G1: 属性意义
A2: DRVMODSIG | B2: read&write | C2: OnChange | E2: int32 | F2: 0 | G2: 驾驶模式信号 0x0: 初始值 0x1: 运动模式 0x2: 舒适模式 0x3: 经济模式 0x4: 雪地模式 0x5: 泥地模式 0x6: 沙地模式 0x7: One-Pedal模式 0x8: E-Auto模式 0x9: 狂暴模式 0xA: 赛道模式 0xB: 极致节能模式 0xC: 个性化模式 0xD: 晕车舒缓模式 0xE~0xF: Reserved 无效值：0xFFFF
A3: DRVMODSHIFTMISOPER | B3: read&write | C3: OnChange | E3: int32 | F3: 0 | G3: 驾驶模式切换误操作 0x0: 正常 0x1: 异常 无效值：0xFFFF
A4: DRVSTYLE | B4: read&write | C4: OnChange | E4: int32 | F4: 0 | G4: 驾驶风格 0x0:初始值 0x1:平和 0x2:正常 0x3:激进 无效值：0xFFFF
A5: LNCHCTRLMODDIRMN | B5: read&write | C5: OnChange | E5: int32 | F5: 0 | G5: 弹射起步模式不启用仪表提醒 0x0:初始值 0x1:整车系统故障，弹射起步模式无法启用 0x2:动力电池剩余电量较低，弹射起步模式无法启用 0x3:智能驾驶功能已激活，弹射起步模式无法启用 0x4:请系安全带后启用弹射起步模式 0x5:请保持车辆静止后启用弹射起步模式 0x6:请挂入D挡后启用弹射起步模式 0x7:请切换为运动/暴走/赛道模式后启用弹射起步模式 0x8:请将方向盘回正后启用弹射起步模式 0x9:请深踩制动踏板后启用弹射起步模式 0xA:请深踩加速踏板后启用弹射起步模式 0xB-0xF：reserved 无效值：0xFFFF
A6: LNCHCTRLTRIGRMN | B6: read&write | C6: OnChange | E6: int32 | F6: 0 | G6: 弹射起步触发提醒 0x0: 初始值 0x1: 条件不满足，弹射起步无法启用（Launch Control unavailable） 0x2:弹射起步模式已启用，请等待扭矩加载（Launch Control available，wait for loading Torque） 0x3: 请快速松开刹车，完成弹射起步（Boost ready，Please release the brake pedal） 0x4-0x7:reserved 无效值：0xFFFF
A7: ACLRTIREQ | B7: read&write | C7: OnChange | E7: int32 | F7: 0 | G7: 加速计时器请求 0x0: 无请求 0x1: 有请求 无效值：0xFFFF
A8: CHRGSTSDISP | B8: read&write | C8: OnChange | E8: int32 | F8: 0 | G8: 充电状态（显示） 0x0: 初始值 0x1:充电准备中 0x2:交流充电中（慢充中） 0x3:无线充电中 0x4:超级充电中 0x5:直流充电中（快充中） 0x6: 交流充电预加热中 0x7: 无线充电预加热中 0x8: 直流充电预加热中 0x9: 交流充电保温中 0xA: 无线充电保温中 0xB: 直流充电保温中 0xC: 充电结束 0xD: 充电故障结束 0xE~0x1F：Reserved 无效值：0xFFFF
A9: VEHEXTDCHASTS | B9: read&write | C9: OnChange | E9: int32 | F9: 0 | G9: 车辆对外放电状态 0x0: 初始值 0x1: 放电准备中 0x2: 放电中 0x3: 放电结束 0x4: 车辆禁止放电 0x5~0x6: Reserved 0x7: Invalid 无效值：0XFFFF
A10: RESVCHRGSTSDISP | B10: read&write | C10: OnChange | E10: int32 | F10: 0 | G10: 充电预约状态（显示） 0x0: 初始值 0x1: 预约充电 0x2: 定时出发 0x3-0x7：Reserved 无效值：0xFFFF
A11: CHRGDISCHRGCRTDISP | B11: read&write | C11: OnChange | E11: int32 | F11: 0 | G11: 充放电电流（显示） 精度为1 充电桩输出电流范围：0-1000A 无效值：0xFFFF
A12: CHRGDCHAPWRDISP | B12: read&write | C12: OnChange | E12: float | F12: 0 | G12: 充放电功率（显示）精度为0.1 有效范围：0-1000 HMI除以10得到正常值 无效值：0xFFFF
A13: RMNGCHRGTIDISPLY | B13: read&write | C13: OnChange | E13: int32 | F13: 0 | G13: 剩余充电时间 显示精度为 min 无效值：0xFFFF
... A64: CHARGE_DISCHARGE_SCHEDULED_VIEW_STATUS | B64: read&write | C64: OnChange | E64: int32 | F64: 0 | G64: 充放电界面显示状态 用于 TT 模块 0：不显示 1：显示

Sheet custom.warning
A1: 属性名 | B1: 读写模式 | C1: 通知模式 | D1: 通知周期 | E1: 属性值类型 | F1: 默认值 | G1: 属性意义
A2: WARNING_DISPLAY_POP | B2: read&write | C2: OnChange | E2: int32 | F2: 0 | G2: 0 不播放报警 非0 播放当前id对应报警
A3: HOOD_DOOR_STS | B3: read&write | C3: OnChange | E3: int32 | F3: 0 | G3: 前舱门（引擎盖）状态 0:关闭（默认） 1：常亮 2：闪烁
A4: DRIVER_DOOR_STS | B4: read&write | C4: OnChange | E4: int32 | F4: 0 | G4: 驾驶侧门 状态 0:关闭（默认） 1：常亮 2：闪烁
A5: PSNGER_DOOR_STS | B5: read&write | C5: OnChange | E5: int32 | F5: 0 | G5: 乘客侧门（副驾驶）状态 0:关闭（默认） 1：常亮 2：闪烁
A6: RHR_DOOR_STS | B6: read&write | C6: OnChange | E6: int32 | F6: 0 | G6: 右后门 状态 0:关闭（默认） 1：常亮 2：闪烁
A7: LHR_DOOR_STS | B7: read&write | C7: OnChange | E7: int32 | F7: 0 | G7: 左后门 状态 0:关闭（默认） 1：常亮 2：闪烁
A8: TRUNK_DOOR_STS | B8: read&write | C8: OnChange | E8: int32 | F8: 0 | G8: 行李箱门 状态 0:关闭（默认） 1：常亮 2：闪烁
A9: ENERGY_MODE | B9: read&write | C9: OnChange | E9: int32 | F9: 0 | G9: 能量模式常显状态 0x0：仪表不显示 0x1：燃油优先 0x2：纯电优先 0x4：强制纯电 0x5：强制发电 0x6：智能模式
A10: WARNING_SHOW_STS | B10: read&write | C10: OnChange | E10: int32 | F10: 0 | G10: 0 没有报警 1 有报警 说明：用于通知TT等是否在报警
A11: SECUBLT_DRIVER | B11: read&write | C11: OnChange | E11: int32 | F11: 0 | G11: 主驾驶安全带状态 0 灭 1 亮（常亮 以及 闪烁 均与TT保持一致） | H11: N8:主驾驶安全带状态 0 灭 1 亮（常亮 以及 闪烁 均与TT保持一致）
A12: SECUBLT_PSNGER | B12: read&write | C12: OnChange | E12: int32 | F12: 0 | G12: 副驾驶安全带状态 0 灭 1 亮（常亮 以及 闪烁 均与TT保持一致） | H12: N8:副驾驶安全带状态 0 灭 1 亮（常亮 以及 闪烁 均与TT保持一致）
A13: SECUBLT_RL | B13: read&write | C13: OnChange | E13: int32 | F13: 0 | G13: 二排左安全带状态 0 灭 1 亮（常亮 以及 闪烁 均与TT保持一致） | H13: N8:三排左安全带状态 0 灭 1 亮（常亮 以及 闪烁 均与TT保持一致）
A14: SECUBLT_RM | B14: read&write | C14: OnChange | E14: int32 | F14: 0 | G14: 二排中安全带状态 0 灭 1 亮（常亮 以及 闪烁 均与TT保持一致） | H14: N8:三排中安全带状态 0 灭 1 亮（常亮 以及 闪烁 均与TT保持一致））
A15: SECUBLT_RR | B15: read&write | C15: OnChange | E15: int32 | F15: 0 | G15: 二排右安全带状态 0 灭 1 亮（常亮 以及 闪烁 均与TT保持一致） | H15: N8:三排右安全带状态 0 灭 1 亮（常亮 以及 闪烁 均与TT保持一致）
A16: BACKLIGHT_REQ | B16: read&write | C16: OnChange | E16: int32 | F16: 0 | G16: 背光开关请求 0 灭 1 亮
A17: ADAS_NOAU_ODD_DIST_INFO | B17: read&write | C17: OnChange | E17: int32 | F17: 0 | G17: 0~1000 NOA(NOAU+NOAH)ODD距离状态提示
A18: WARNING_DISPLAY_POP_M | B18: read&write | C18: OnChange | E18: int32 | F18: 0 | G18: 0 不播放报警 非0 播放当前id对应报警 播放区域：中央middle行车电脑区域 | H18: AL_北汽 N80KS_SRD-仪表指示灯和文字告警及Chime报警音定义_v1.0 第41行注2：智驾弹窗的放置位置：智驾功能相关的放中央、智驾硬件故障(传感器、摄像头)相关的放右边，具体参照sheet05
A19: WARNING_DISPLAY_POP_R | B19: read&write | C19: OnChange | E19: int32 | F19: 0 | G19: 0 不播放报警 非0 播放当前id对应报警 播放区域：右侧行车电脑区域right | H19: AL_北汽 N80KS_SRD-仪表指示灯和文字告警及Chime报警音定义_v1.0 第41行注2：智驾弹窗的放置位置：智驾功能相关的放中央、智驾硬件故障(传感器、摄像头)相关的放右边，具体参照sheet05
A20: THERMAL_RUNAWAY_FAULT | B20: read&write | C20: OnChange | E20: int32 | F20: 0 | G20: 热失控告警 0::未触发 1：触发
A21: SECUBLT_MIDDLE_RL | B21: read&write | C21: OnChange | E21: int32 | F21: 0 | G21: N5不用 | H21: N8:二排左安全带状态 0 灭 1 亮（常亮 以及 闪烁 均与TT保持一致）
A22: SECUBLT_MIDDLE_RR | B22: read&write | C22: OnChange | E22: int32 | F22: 0 | G22: N5不用 | H22: N8:二排右安全带状态 0 灭 1 亮（常亮 以及 闪烁 均与TT保持一致）
A23: MAINTENANCE_MILEAGE_REMAINING | B23: read&write | C23: OnChange | E23: int32 | F23: 0 | G23: N5不用 | H23: N8:距离下次保养里程 xx km
A24: ACC_GAP | B24: read&write | C24: OnChange | E24: int32 | F24: 0 | G24: 时距档位 0:未触发 1:时距一档（距离前车近） 2:时距二档（距离前车较近） 3:时距三档（距离前车适中） 4:时距四档（距离前车较远） 5:时距五档（距离前车远）
A25: TRUNK_DOOR_ANIM_STS | B25: read&write | C25: OnChange | E25: int32 | F25: 0 | G25: 0:关 1:开
A26: TPMS_EXCEPTION | B26: read&write | C26: OnChange | E26: int32 | F26: 0 | G26: 0:无异常 1:有异常
A27: SEAT_BELT_WARNING_TYPE | B27: read&write | C27: OnChange | E27: int32 | F27: 0 | G27: 0：无响应 1：播无小字的告警 2：播有小字的告警

Sheet custom.telltale
A1: 属性名 | B1: 读写模式 | C1: 通知模式 | D1: 通知周期 | E1: 属性值类型 | F1: 默认值 | G1: 属性意义（N50) | I1: 属性意义（N80) | J1: N80 N50对比 | K1: N80共同灯位
A2: POSITION_LIGHT | B2: read&write | C2: OnChange | E2: int32 | F2: 0 | G2: 位置指示灯 0x01:点亮 0x00:熄灭 | I2: 位置指示灯 0x01:点亮 0x00:熄灭 闪烁：0-1跳变 | J2: N80新增闪烁效果
A3: REAR_FOG_LIGHT | B3: read&write | C3: OnChange | E3: int32 | F3: 0 | G3: 后雾灯指示灯 0x01:点亮 0x00:熄灭 | I3: 后雾灯指示灯 0x01:点亮 0x00:熄灭 闪烁：0-1跳变 | J3: N80新增闪烁效果
A4: LOW_BEAM_LIGHT | B4: read&write | C4: OnChange | E4: int32 | F4: 0 | G4: 近光灯指示灯 0x01:点亮 0x00:熄灭 | I4: 近光灯指示灯 0x01:点亮 0x00:熄灭 | J4: N80新增闪烁效果
A5: HIGH_BEAM_LIGHT | B5: read&write | C5: OnChange | E5: int32 | F5: 0 | G5: 远光灯指示灯 0x01:点亮 0x00:熄灭 | I5: 远光灯指示灯 0x01:点亮 0x00:熄灭 | J5: N80新增闪烁效果
A6: VCU_AUTHENTICATION_FAILED_LIGHT | B6: read&write | C6: OnChange | E6: int32 | F6: 0 | G6: 动力防盗认证失败指示灯 0x01:点亮 0x00:熄灭 | H6: 动态灯 | I6: 动力防盗认证失败指示灯 0x01:点亮 0x00:熄灭 | J6: 一致
A7: PDCU_ENERGY_STOP_LIGHT | B7: read&write | C7: OnChange | E7: int32 | F7: 0 | G7: 制动能量回收关闭指示灯 0x01:点亮 0x00:熄灭 | I7: 制动能量回收关闭指示灯 0x01:点亮 0x00:熄灭 | J7: 一致
A8: CHARGE_DISCHARGE_CONNECT_LIGHT | B8: read&write | C8: OnChange | E8: int32 | F8: 0 | G8: 充放电连接状态指示灯 0x01:点亮 0x00:熄灭 | I8: 充放电连接状态指示灯 0x01:点亮 0x00:熄灭 | J8: 一致
A9: LIMIT_DRIVE_POWER_LIGHT | B9: read&write | C9: OnChange | E9: int32 | F9: 0 | G9: 驱动功率限制指示灯 0x01:点亮 0x00:熄灭 | I9: 驱动功率限制指示灯 0x01:点亮 0x00:熄灭 | J9: 一致
A10: COMMON_BREAK_LIGHT | B10: read&write | C10: OnChange | E10: int32 | F10: 0 | G10: 常规故障指示灯 0x01:点亮 0x00:熄灭 | I10: N80无此灯 | J10: N80无此灯
A11: SINGLE_PEDAL_LIGHT | B11: read&write | C11: OnChange | E11: int32 | F11: 0 | G11: 单踏板保持指示灯 0x01:点亮灰色灯 0x02:点亮蓝色灯 0x00:熄灭 | H11: 动态灯 | I11: 单踏板保持指示灯 0x01:点亮灰色灯 0x02:点亮蓝色灯 0x03: 点亮黄色故障灯 0x00:熄灭 | J11: 一致
A12: DOOR_OPEN_LIGHT | B12: read&write | C12: OnChange | E12: int32 | F12: 0 | G12: 门开指示灯 0x01:点亮 0x00:熄灭 闪烁:1-0之间跳变 | I12: 门开指示灯 0x01:点亮 0x00:熄灭 闪烁:1-0之间跳变 | J12: 一致
A13: LEFT_TURN_LIGHT | B13: read&write | C13: OnChange | E13: int32 | F13: 0 | G13: 左转向指示灯 0x01:开启 0x00:关闭 闪烁:1-0之间跳变 | I13: 左转向指示灯 0x01:开启 0x00:关闭 闪烁:1-0之间跳变 | J13: 一致
A14: RIGHT_TURN_LIGHT | B14: read&write | C14: OnChange | E14: int32 | F14: 0 | G14: 右转向指示灯 0x01:开启 0x00:关闭 闪烁:1-0之间跳变 | I14: 右转向指示灯 0x01:开启 0x00:关闭 闪烁:1-0之间跳变 | J14: 一致
A15: SYSBRAKE_FAIL_LIGHT | B15: read&write | C15: OnChange | E15: int32 | F15: 0 | G15: 制动系统故障指示灯 0x01:红色灯 0x02:黄色灯 0x00:熄灭 | I15: 制动系统故障指示灯 0x01:红色灯 0x02:黄色灯 0x00:熄灭 闪烁：1-0跳变 | J15: 新增红色灯闪烁效果
A16: DANGER_WARN_LIGHT | B16: read&write | C16: OnChange | E16: int32 | F16: 0 | G16: 危险告警指示灯 0x01:开启 0x00:关闭 闪烁:1-0之间跳变 | I16: 危险告警指示灯 0x01:开启 0x00:关闭 闪烁:1-0之间跳变 | J16: 一致
A17: AIRBAG_WARN_LIGHT | B17: read&write | C17: OnChange | E17: int32 | F17: 0 | G17: 安全气囊故障告警指示灯 亮灭状态 0x01:点亮 0x00:熄灭 闪烁:1-0之间跳变 | H17: 动态灯 | I17: 安全气囊故障告警指示灯 亮灭状态 0x01:点亮 0x00:熄灭 闪烁:1-0之间跳变 | J17: 一致
A18: AIRBAG_WARN_BLINK | B18: read&write | C18: OnChange | E18: int32 | F18: 0 | G18: 安全气囊故障告警指示灯 是否为闪烁状态 0x00:非闪烁 0x01:闪烁 | I18: 安全气囊故障告警指示灯 是否为闪烁状态 0x00:非闪烁 0x01:闪烁
A19: ABS_FAIL_LIGHT | B19: read&write | C19: OnChange | E19: int32 | F19: 0 | G19: ABS故障指示灯 0x01:点亮 0x00:熄灭 | I19: ABS故障指示灯 0x01:点亮 0x00:熄灭 闪烁：1-0跳变 | J19: 新增闪烁效果
A20: SYS_CHARGE_FAIL_LIGHT | B20: read&write | C20: OnChange | E20: int32 | F20: 0 | G20: 充电系统故障指示灯 0x01:点亮 0x00:熄灭 | I20: 充电系统故障指示灯 0x01:点亮红色灯，0x02：点亮黄色灯 0x00:熄灭 闪烁: 信号跳变 | J20: 一致
A21: EPB_BRAKE_MODE_LIGHT | B21: read&write | C21: OnChange | E21: int32 | F21: 0 | G21: EPB驻车制动状态指示灯 亮灭状态 0x01:点亮 0x00:熄灭 闪烁:1-0之间跳变 | H21: 动态灯 | I21: EPB驻车制动状态指示灯 亮灭状态 0x01:点亮 0x00:熄灭 闪烁:1-0之间跳变 | J21: 新增两种闪烁频率 | K21: 共灯位
A22: EPB_BRAKE_MODE_BLINK | B22: read&write | C22: OnChange | E22: int32 | F22: 0 | G22: EPB驻车制动状态指示灯 是否为闪烁状态 0x00:非闪烁 0x01:闪烁 | I22: EPB驻车制动状态指示灯 是否为闪烁状态 0x00:非闪烁 0x01:闪烁
A23: EPB_FAIL_LIGHT | B23: read&write | C23: OnChange | E23: int32 | F23: 0 | G23: EPB故障告警指示灯 0x01:点亮 0x00:熄灭 | H23: 动态灯 | I23: EPB故障告警指示灯 亮灭状态 0x01:点亮 0x00:熄灭 闪烁:1-0之间跳变 | J23: 新增两种闪烁频率
A24: EPB_FAIL_BLINK | B24: read&write | C24: OnChange | E24: int32 | F24: 0 | I24: 新增EPB故障告警指示灯 是否为闪烁状态 0x00:非闪烁 0x01:闪烁
A25: ESP_MODE_LIGHT | B25: read&write | C25: OnChange | E25: int32 | F25: 0 | G25: ESP工作及故障告警指示灯 亮灭状态 0x01:点亮 0x00:熄灭 闪烁:1-0之间跳变 | H25: 动态灯 | I25: ESP工作及故障告警指示灯 亮灭状态 0x01:点亮 0x00:熄灭 闪烁:1-0之间跳变 | J25: 新增两种闪烁频率 | K25: 共灯位
A26: ESP_MODE_BLINK | B26: read&write | C26: OnChange | E26: int32 | F26: 0 | G26: ESP工作及故障告警指示灯 是否为闪烁状态 0x00:非闪烁 0x01:闪烁 | I26: ESP工作及故障告警指示灯 是否为闪烁状态 0x00:非闪烁 0x01:闪烁
A27: ESP_CLOSE_LIGH | B27: read&write | C27: OnChange | E27: int32 | F27: 0 | G27: ESP关闭指示灯 0x01:点亮 0x00:熄灭 | H27: 动态灯 | I27: ESP关闭指示灯 亮灭状态 0x01:点亮 0x00:熄灭 闪烁:1-0之间跳变 | J27: 新增闪烁效果
A28: ESP_CLOSE_BLINK | B28: read&write | C28: OnChange | E28: int32 | F28: 0 | I28: ESP关闭指示灯 是否为闪烁状态 0x00:非闪烁 0x01:闪烁
A29: NOT_SAFETY_BELT_LIGHT | B29: read&write | C29: OnChange | E29: int32 | F29: 0 | G29: 安全带未系告警指示灯（N50 N51 3.0适用）0x01:点亮 0x00:熄灭 闪烁:1-0之间跳变 | I29: 主驾安全带未系告警指示灯 0x01:点亮主驾未系 0x00:熄灭 闪烁:信号之间跳变 | J29: 不一致，新增多种安全带显示效果 | K29: N80，新增多种安全带显示效果
A30: MAIN_SAFETY_BELT_LIGHT | B30: read&write | C30: OnChange | E30: int32 | F30: 0 | G30: 仅针对N51 HMI4.0提供 主驾驶 0x01:点亮 0x00:熄灭 闪烁:1-0之间跳变
A31: PASS_SAFETY_BELT_LIGHT | B31: read&write | C31: OnChange | E31: int32 | F31: 0 | G31: 仅针对N51 HMI4.0提供 副驾驶 0x01:点亮 0x00:熄灭 闪烁:1-0之间跳变
A32: SECOND_SAFETY_BELT_LIGHT | B32: read&write | C32: OnChange | E32: int32 | G32: 针对N51 HMI4.0提供 二排 0x01:点亮左未系 0x02:中未系 0x04:右未系 0x03:左中 0x05:左右 0x06:中右 0x07：全部未系 0x00:熄灭 闪烁:信号之间跳变
A33: NOT_SAFETY2_BELT_LIGHT | B33: read&write | C33: OnChange | E33: int32 | I33: 副驾安全带未系告警指示灯 0x01:点亮未系 0x00:熄灭 闪烁:信号之间跳变 | K33: N80，新增多种安全带显示效果
A34: NOT_SAFETY3_BELT_LIGHT | B34: read&write | C34: OnChange | E34: int32 | I34: 二排安全带未系告警指示灯 0x01:点亮左未系 0X02：点亮右未系 0x03:点亮都未系 0x00:熄灭 闪烁:信号之间跳变 | K34: N80，新增多种安全带显示效果
A35: NOT_SAFETY4_BELT_LIGHT | B35: read&write | C35: OnChange | E35: int32 | I35: 三排安全带未系告警指示灯 0x01:点亮左未系 0x02:中未系 0x04:右未系 0x03:左中 0x05:左右 0x06:中右 0x07：全部未系 0x00:熄灭 闪烁:信号之间跳变 | K35: N80，新增多种安全带显示效果
A36: CHARGE_REMIND_LIGHT | B36: read&write | C36: OnChange | E36: int32 | F36: 0 | G36: 充电提醒指示灯 0x01:点亮 0x00:熄灭 | I36: 充电提醒指示灯 0x00:熄灭 0x02:点亮灰色 0x01:黄灭 | J36: 一致 | K36: N80，新增状态
A37: TPMS_WARN_LIGHT | B37: read&write | C37: OnChange | E37: int32 | F37: 0 | G37: TPMS故障告警指示灯 亮灭状态 0x01:点亮 0x00:熄灭 | H37: 动态灯 | I37: TPMS故障告警指示灯 亮灭状态 0x01:点亮 0x00:熄灭 | J37: 一致
A38: TPMS_WARN_BLINK_LIGHT | B38: read&write | C38: OnChange | E38: int32 | G38: TPMS故障告警指示灯 是否为闪烁状态 0x00:非闪烁 0x01:闪烁 | I38: TPMS故障告警指示灯 是否为闪烁状态 0x00:非闪烁 0x01:闪烁 | J38: 一致
A39: SYSTEM_WARN_LIGHT | B39: read&write | C39: OnChange | E39: int32 | F39: 0 | G39: 系统故障告警指示灯 0x01:点亮 0x00:熄灭 | I39: 系统故障告警指示灯 0x01:点亮 0x00:熄灭 | J39: 一致
A40: READY_MODE_LIGHT | B40: read&write | C40: OnChange | E40: int32 | F40: 0 | G40: Ready状态指示灯 0x01:点亮 0x00:熄灭 | I40: Ready状态指示灯 0x01:点亮 0x00:熄灭 | J40: 一致
...

Sheet custom.hmi
A1: 属性名 | B1: 读写模式 | C1: 通知模式 | D1: 通知周期 | E1: 属性值类型 | F1: 默认值 | G1: 属性意义
A2: HMI_RENDER_STATE | B2: read&write | C2: OnChange | E2: int32 | F2: 0 | G2: 0 Wait 1 Ready
A3: STANDBY_BUTTON | B3: read&write | C3: OnEvent | E3: int32 | F3: 0 | G3: 点击功能按钮(HMI 通知 Midware) 0 - 无点击 1 - 车门锁按钮 2 - 充电口按钮 3 - 后备箱按钮 4 - 后视镜按钮 5 - 加油口按钮 6 - 后视镜弹窗按钮 7 - 遮阳帘按钮
A4: TOUCH_BAREA_BUTTON | B4: read&write | C4: OnEvent | E4: int32 | F4: 0 | G4: 有报警时点击仪表B区(HMI 通知 Midware) 1 - 取消报警请求
A5: HMI_MENU_PAGE | B5: read&write | C5: OnChange | E5: int32 | F5: 2 | G5: 0-电话 1-导航 2-多媒体 3-胎压 4-总里程 5-本次里程
A6: HMI_MENU_COUNT | B6: read&write | C6: OnChange | E6: int32 | F6: 0 | G6: 当前页面的总数
A7: HMI_MENU_INDEX | B7: read&write | C7: OnChange | E7: int32 | F7: 0 | G7: 当前在第几个页面
A8: HMI_MENU_BAR_STATE | B8: read&write | C8: OnChange | E8: int32 | F8: 0 | G8: 0-不显示 1-显示
A9: HMI_ADAS_BUTTON | B9: read&write | C9: OnEvent | E9: int32 | F9: 0 | G9: A区ADAS投屏按钮点击 0-默认值 1-点击
A10: SLIDE_UP_BUTTON | B10: read&write | C10: OnEvent | E10: int32 | F10: 0 | G10: N51AS HMI4.0 有报警时上滑关闭弹窗(HMI 通知 Midware) 1 - 取消报警请求

Sheet custom.mcu
A1: 属性名 | B1: 读写模式 | C1: 通知模式 | D1: 通知周期 | E1: 属性值类型 | F1: 默认值 | G1: 属性意义 | H1: 命令
A2: SPEED_VALUE | B2: read | E2: int32 | F2: 0 | G2: 车速值（原始值x100） 精度：1km/h 无效值：0xFFFF，HMI对应显示“--km/h”或“--mph”
A3: POWER_VALUE | B3: read | C3: OnChange | E3: int32 | F3: 0 | G3: 电量 0~100% 无效值：0xFF
A4: POWER_PERCENT | B4: read | C4: OnChange | E4: int32 | F4: 0 | G4: 功率百分比 数据范围：0~200 显示范围：-100~100 偏移量：-100 无效值：0xFF，HMI对应显示“--%”
A5: GEAR_TYPE | B5: read | C5: OnChange | E5: int32 | F5: 0 | G5: 档位 0x0: NO Display 0x1: P挡 0x2: N挡 0x3: R挡 0x4: D挡 无效值：0xFF
A6: FUEL_PERCENT | B6: read | C6: OnChange | E6: int32 | F6: 0 | G6: 剩余油量百分比 0~100% 无效值：0xFF
A7: EVDTE_VALUE | B7: read | C7: OnChange | E7: int32 | F7: 0 | G7: 续驶里程(纯电) 0~999Km 无效值：0xFFFF，HMI对应显示“--%”
A8: DRV_PWRLIM_PERC | B8: read | C8: OnChange | E8: int32 | F8: 0 | G8: 驱动功率限值百分比 数据范围：100~200 显示范围：0~100 偏移量：-100 无效值：0xFF，HMI对应显示“--%”
A9: EGYFB_PWRLIM_PERC | B9: read | C9: OnChange | E9: int32 | F9: 0 | G9: 能量回馈功率限值百分比 数据范围：0~100 显示范围：-100~0 偏移量：-100 无效值：0xFF，HMI对应显示“--%”
A10: DTE_VALUE | B10: read | C10: OnChange | E10: int32 | F10: 0 | G10: 续驶里程(燃油) 0-2000 = TC_DTE_NORMAL 0xFFFD = TC_DTE_NOT_DISPLAY 0xFFFE = TC_DTE_LOW 0xFFFF = TC_DTE_INVALID 无效值：0xFFFF，HMI对应显示“--km”
A11: DTE_UNIT | B11: read | C11: OnChange | E11: int32 | F11: 0 | G11: 续驶里程(燃油)单位 0x00 = km 0x01 = mile 无效值：0xFF
A12: THISDRIVERTIME_MINUTE | B12: read | C12: OnChange | E12: int32 | F12: 0 | G12: 本次行驶时间分钟数 正常值0-59999 无效值：60000
A13: THISTRIPVALUE | B13: read | C13: OnChange | E13: int32 | F13: 0 | G13: 本次行驶里程 精度1m HMI需要显示KM除以1000 正常值 0-9999900 无效值：0xFFFFFFFF
A14: GPIOHW_KL15_STATE | B14: read | C14: OnChange | E14: int32 | F14: 0 | G14: KL15状态 0x0: low 0x1: high 无效值：0
... A22: PDC_CHIMEREQ | B22: read | C22: OnChange | E22: int32 | F22: 0 | G22: 0：无声音请求 1：后方障碍物报警长鸣 2：后方障碍物报警间歇鸣叫1（5Hz） 3：后方障碍物报警间歇鸣叫2（3Hz） 4：后方障碍物报警间歇鸣叫3（1Hz） 5：前方障碍物报警长鸣 6：前方障碍物报警间歇鸣叫1（5Hz） 7：前方障碍物报警间歇鸣叫2（3Hz） 8：左侧方障碍物报警长鸣 9：左侧方障碍物报警间歇鸣叫1（5Hz） 10：右侧方障碍物报警长鸣 11：右侧方障碍物报警间歇鸣叫1（5Hz） 12：上电自检系统故障（长鸣3S） 13-15：预留 13：提示音一（启动APA）（reserve） 14：提示音二（找到车位）（reserve） 15：提示音三（APA失效退出）（reserve）
A23: FUEL_SENSOR_STATE | B23: read | C23: OnChange | E23: int32 | G23: 燃油组织传感器状态 1:阻值正常 0:阻值故障 丢失值0
A24: PDC_ADRC_STATES | B24: read | C24: OnChange | E24: array | F24: [ , , ] | G24: 乌龟图信息 PDC_FLCSectorWarning 前左角区域图像分段报警 0：无障碍物 1：Range1 2：Range2 3：Range3 4：Range4 5：Range5 6：探头故障 7：Reserved预留 8：无效invalid PDC_FLMSectorWarning 前左中区域图像分段报警 0：无障碍物 1：Range1 2：Range2 3：Range3 4：Range4 5：Range5 6：探头故障 7：Reserved预留 8：无效invalid PDC_FRMSectorWarning 前右中区域图像分段报警 0：无障碍物 1：Range1 2：Range2 3：Range3 4：Range4 5：Range5 6：探头故障 7：Reserved预留 8：无效invalid PDC_FRCSectorWarning 前右角区域图像分段报警 0：无障碍物 1：Range1 2：Range2 3：Range3 4：Range4 5：Range5 6：探头故障 7：Reserved预留 8：无效invalid PDC_RLCSectorWarning 后左角区域图像分段报警 0：无障碍物 1：Range1 2：Range2 3：Range3 4：Range4 5：Range5 6：Range6 7：Range7 8：探头故障 9：Reserved预留 10：无效invalid PDC_RLMSectorWarning 后左中区域图像分段报警 0：无障碍物 1：Range1 2：Range2 3：Range3 4：Range4 5：Range5 6：Range6 7：Range7 8：探头故障 9：Reserved预留 10：无效invalid PDC_RRMSectorWarning 后右中区域图像分段报警 0：无障碍物 1：Range1 2：Range2 3：Range3 4：Range4 5：Range5 6：Range6 7：Range7 8：探头故障 9：Reserved预留 10：无效invalid PDC_RRCSectorWarning 后右角区域图像分段报警 0：无障碍物 1：Range1 2：Range2 3：Range3 4：Range4 5：Range5 6：Range6 7：Range7 8：探头故障 9：Reserved预留 10：无效invalid ADRC_FLS1SectorWarning 前左侧1区域图像分段报警 0：无障碍物 1：Range1 2：Range2 3：探头故障 ADRC_FLS2SectorWarning 前左侧2区域图像分段报警 0：无障碍物 1：Range1 2：Range2 3：探头故障 ADRC_RLS1SectorWarning 后左侧1区域图像分段报警 0：无障碍物 1：Range1 2：Range2 3：探头故障 ADRC_RLS2SectorWarning 后左侧2区域图像分段报警 0：无障碍物 1：Range1 2：Range2 3：探头故障 ADRC_FRS1SectorWarning 前右侧1区域图像分段报警 0：无障碍物 1：Range1 2：Range2 3：探头故障 ADRC_FRS2SectorWarning 前右侧2区域图像分段报警 0：无障碍物 1：Range1 2：Range2 3：探头故障 ADRC_RRS1SectorWarning 后右侧1区域图像分段报警 0：无障碍物 1：Range1 2：Range2 3：探头故障 ADRC_RRS2SectorWarning 后右侧2区域图像分段报警 0：无障碍物 1：Range1 2：Range2
A25: PDC_FRONT_SYS_STATUS | B25: read | C25: OnChange | E25: int32 | F25: 0 | G25: 前方雷达工作状态 0：Disable 1：Enable 激活 2：Standby准备 3：System Failure系统故障
A26: PDC_REAR_SYS_STATUS | B26: read | C26: OnChange | E26: int32 | F26: 0 | G26: 后方雷达工作状态 0：Disable 1：Enable 激活 2：Standby准备 3：System Failure系统故障
A27: GAUGE_SOC_PRECISION_FLAG | B27: read | C27: OnChange | E27: int32 | F27: 0 | G27: N80 电量表数据精度标志位 N80需求要求在超级充电状态下 电量表显示后两位小数；正常充电显示整数 0：低精度（显示整数） 1：高精度（显示小数） 无效值：0xFF
A28: GAUGE_SOC_PERCENT_N80 | B28: read | C28: OnChange | E28: int32 | F28: 0 | G28: N80 电量表显示数据（百分比） 取值范围：【0 - 10000】 精度0.01 ----（mcu x100 传给 soc ==》hmi, 在高精度情况下 hmi ，需要 % 100 取余，获取小数部分） 无效值：0xFFFF
A29: GPIOHW_OIL_PRESSURE_STATE | B29: read | C29: OnChange | E29: int32 | F29: 0 | G29: 机油压力 0------off 1-------on
A30: TT_LRTurnLight_N80 | B30: read | C30: OnChange | E30: int32 | F30: 0 | G30: 转向状态 0：OFF 1：左转 2：右转 3：双闪
A31: PDC_3DTONEREQ | B31: read | C31: OnChange | E31: int32 | F31: 0 | G31: 0：无声音请求 1：障碍物位于前方左侧（FL） 2：障碍物位于前方右侧（FR） 3：障碍物位于后方左侧（RL） 4：障碍物位于后方右侧（RR）
A32: N80ODOError | B32: read | C32: OnChange | E32: int32 | F32: 0 | G32: N80总里程备份异常标志位 0：无异常 1 ：异常 初始化值为 0

Sheet custom.power
A1: 属性名 | B1: 读写模式 | C1: 通知模式 | D1: 通知周期 | E1: 属性值类型 | F1: 默认值 | G1: 属性意义
A2: CLUSTER_ANIMATION_STATUS | B2: read&write | C2: OnChange | E2: int32 | F2: 0 | G2: 0 未播放仪表开机动画 1 播放仪表开机动画中 2 仪表开机动画结束
A3: IVI_ANIMATION_STATUS | B3: read&write | C3: OnChange | E3: int32 | F3: 0 | G3: 0 未播放中控开机动画 1 播放中控开机动画中 2 中控开机动画结束
A4: POWER_MODE | B4: read&write | C4: OnChange | E4: int32 | F4: 0 | G4: //电源模式枚举定义 enum PowerMode { PWR_MODE_NONE = 0; PWR_MODE_STR = 1; //STR模式 PWR_MODE_STANDBY = 2; //待机模式 PWR_MODE_RUN = 3; //工作模式 PWR_MODE_SLEEP = 4; //睡眠模式 PWR_MODE_ABNORMAL = 5; //异常模式 PWR_MODE_TEMP_RUN = 6; //临时模式 PWR_MODE_CHARGGING = 7; //充电模式 }
A5: READY | B5: read&write | C5: OnChange | E5: int32 | F5: 0 | G5: PowerMode组件是否就绪 0：PowerMode未就绪 1或2：PowerMode就绪 （仅用于STR，各模块在收到此信号后再进行STR的注册）
A6: STR_REGISTER | B6: read&write | C6: OnEvent | E6: string | F6: “” | G6: 用于各模块向power注册STR，各模块注册自己的名字（如果不需要回复ack，则无需注册）
A7: STR_SUSPEND_PREPARE_ACK | B7: read&write | C7: OnEvent | E7: string | F7: “” | G7: 用于各模块向power回复suspend ack 注：名字必须和REGISTER的名字保持一致
A8: STR_SUSPEND_STATUS | B8: read&write | C8: OnEvent | E8: int32 | F8: 0 | G8: 0：无效值，收到即return即可(当前处于正常工作状态或STR完全结束） 1：进入STR(suspend) 2：退出STR(resume)
A9: STR_SUSPEND_RESUME_ACK | B9: read&write | C9: OnEvent | E9: string | F9: "" | G9: 用于各模块向power回复resume ack 注：名字必须和REGISTER的名字保持一致
A10: POWER_STATE | B10: read&write | C10: OnChange | E10: int32 | F10: 0 | G10: 整车电源状态 0-power off 1-power on
A11: WHUD_HMI_READY | B11: read&write | C11: OnChange | E11: int32 | F11: 0 | G11: WHUD启动状态 0-WHUD未就绪 1-WHUD就绪
A12: IVI_ANIM_LOGO_MOVE | B12: read&write | C12: OnChange | E12: int32 | F12: 0 | G12: 动画已经播放到过LOGO偏移处 0-未播放到过偏移处 1-播放到过偏移处
A13: VOLTAGE_ABNORMAL_EVENT | B13: read&write | C13: OnChange | E13: int32 | F13: 0 | G13: 供电电压等级 0-正常电压 1-低压缓冲 2-高压缓冲 3-超低压 4-超高压
A14: POWER_ONOFF_REASON | B14: read&write | C14: OnChange | E14: int32 | F14: 100 | G14: enum PowerOnOffReason { PWR_ON_COLD = 0; //KL30冷启动开机或者睡眠模式下收到CAN/KL15唤醒 PWR_ON_FACRORY_RESET = 1; //android工程模式重启 PWR_ON_CMD_REBOOT = 2; //android ADB REBOOT请求MCU重启SOC PWR_ON_FROM_ABNORMAL_BY_RESET = 3; //异常模式下恢复（Reset方案） PWR_ON_STR_INTERRUPTED_RESET_ACIC = 4; //STR中断-被唤醒SM主动RESET整板 PWR_ON_WAKEUP_FROM_STR_BY_KL15 = 5; //STR正常恢复到待机模式（STR模式下收到CAN/KL15唤醒） PWR_ON_WAKEUP_FROM_STR_BY_RTC = 6; //STR正常恢复到待机模式（闹钟自唤醒） PWR_ON_WAKEUP_FROM_SLEEP_BY_RTC = 7; //睡眠模式下恢复到待机模式（闹钟自唤醒） PWR_ON_BY_POWERKEY_RESET = 8; //方控长按10s powerkey 重启 PWR_ON_MCU_WDT_RESET = 9; //WDT重启 PWR_ON_OTA_RESET = 10; //OTA重启 PWR_ON_STR_TIMEOUT = 11; //STR超时/STR进入失败-SM主动reset整板 PWR_ON_SOC_RESCUE_RESET = 12; //android救援模式重启 PWR_OFF_STR = 13; //STR休眠开始 PWR_ON_SOC_RECOVERY_RESET = 14; //Soc恢复出厂设置重启 PWR_ON_BSW_RESET = 15; //其他原因(BSW) PWR_ON_DIAG_RESET = 16; //诊断重启 PWR_ON_FROM_ABNORMAL_MODE = 17; //电压异常恢复（预留） PWR_ON_STR_INTERRUPTED_RESET_SOC = 18; //STR中断-被唤醒SM主动RESETSOC（预留） PWR_ON_STR_FAILED_RESET_SOC = 19; //STR超时/STR进入失败-SM主动reset SOC（预留）· PWR_OFF_WITH_STR_COUNTING_RESET = 20; //STR休眠次数达到需求次数时重启 PWR_ON_PRE_SENTRY_MODE_RESET = 21;//启动哨兵模式前的重启 PWR_ON_OFF_SOC_INVALID = 100; //无效值 }

Sheet custom.hardkey
A1: 属性名 | B1: 读写模式 | C1: 通知模式 | D1: 通知周期 | E1: 属性值类型 | F1: 默认值 | G1: 属性意义
A2: SELRI | B2: read&write | C2: OnChange | E2: int32 | F2: 0 | G2: （···）键事件 0：无此按键事件发生 1：有此按键事件发生

Sheet psis.car_cfg
A1: 属性名 | B1: 读写模式 | C1: 通知模式 | D1: 通知周期 | E1: 属性值类型 | F1: 默认值 | G1: 属性意义 | H1: 所属诊断描述 | I1: PSIS结构名 | J1: PSIS属性名 | K1: PSIS头文件名
A2: CAR_CFG_HUD_TYPE | B2: read | C2: OnChange | D2: 0 | E2: int32 | F2: 0 | G2: HUD抬头显示 0x0 无HUD 0x1 W-HUD 0x2 AR-HUD reserved | I2: Did0xf011 | J2: HUD_TYPE | K2: cfg_cal.h
A3: CAR_CFG_AEB | B3: read | C3: OnChange | D3: 0 | E3: int32 | F3: 0 | G3: AEB自动紧急制动系统 reserved | I3: Did0xf011 | J3: AEB | K3: cfg_cal.h
A4: CAR_CFG_FCW | B4: read | C4: OnChange | D4: 0 | E4: int32 | F4: 0 | G4: FCW车辆前碰撞预警 reserved | I4: Did0xf011 | J4: FCW | K4: cfg_cal.h
A5: CAR_CFG_ACC | B5: read | C5: OnChange | D5: 0 | E5: int32 | F5: 0 | G5: ACC自适应巡航 reserved | I5: Did0xf011 | J5: ACC | K5: cfg_cal.h
A6: CAR_CFG_ICA | B6: read | C6: OnChange | D6: 0 | E6: int32 | F6: 0 | G6: ICA集成式巡航 reserved | I6: Did0xf011 | J6: ICA | K6: cfg_cal.h
A7: CAR_CFG_TSR | B7: read | C7: OnChange | D7: 0 | E7: int32 | F7: 0 | G7: TSR交通标识识别 reserved | I7: Did0xf011 | J7: TSR | K7: cfg_cal.h
A8: CAR_CFG_ISA | B8: read | C8: OnChange | D8: 0 | E8: int32 | F8: 0 | G8: ISA智能限速告警 reserved | I8: Did0xf011 | J8: ISA | K8: cfg_cal.h
A9: CAR_CFG_LDW | B9: read | C9: OnChange | D9: 0 | E9: int32 | F9: 0 | G9: LDW车道偏离预警系统 reserved | I9: Did0xf011 | J9: LDW | K9: cfg_cal.h
A10: CAR_CFG_LCA | B10: read | C10: OnChange | D10: 0 | E10: int32 | F10: 0 | G10: LCA变道辅助 reserved | I10: Did0xf011 | J10: LCA | K10: cfg_cal.h
A11: CAR_CFG_DOW | B11: read | C11: OnChange | D11: 0 | E11: int32 | F11: 0 | G11: DOW开门预警 reserved | I11: Did0xf011 | J11: DOW | K11: cfg_cal.h
A12: CAR_CFG_FCTA | B12: read | C12: OnChange | D12: 0 | E12: int32 | F12: 0 | G12: FCTA前向交通穿行提示 reserved | I12: Did0xf011 | J12: FCTA | K12: cfg_cal.h
A13: CAR_CFG_RCTA | B13: read | C13: OnChange | D13: 0 | E13: int32 | F13: 0 | G13: RCTA后向交通穿行提示 reserved | I13: Did0xf011 | J13: RCTA | K13: cfg_cal.h
... A87: CAR_CFG_CURB_WEIGHT | B87: read | C87: OnChange | D87: 0 | E87: int32 | F87: 0 | G87: 车身质量 0x0 1950kg 0x1 1970kg 0x2 2050kg 0x3 1936kg | I87: Did0xf011 | J87: CURB_WEIGHT | K87: cfg_cal.h

Sheet psis.car_cfg.n80
A1: 属性名 | B1: 读写模式 | C1: 通知模式 | D1: 通知周期 | E1: 属性值类型 | F1: 默认值 | G1: 属性意义 | H1: 所属诊断描述 | I1: PSIS结构名 | J1: PSIS属性名 | K1: PSIS头文件名
A2: CAR_CFG_VEHICLE_VARIANT | B2: read | C2: OnChange | D2: 0 | E2: int32 | F2: 0 | G2: Vehicle Variant 车型配置 | I2: Did0xf011 | J2: VEHICLE_VARIANT | K2: cfg_cal.h
A3: CAR_CFG_LANGUAGE | B3: read | C3: OnChange | D3: 0 | E3: int32 | F3: 0 | G3: Language 默认语言 | I3: Did0xf011 | J3: LANGUAGE | K3: cfg_cal.h
A4: CAR_CFG_REVERSE_VIEW_CONFIG | B4: read | C4: OnChange | D4: 0 | E4: int32 | F4: 0 | G4: 倒车影像配置 | I4: Did0xf011 | J4: REVERSE_VIEW_CONFIG | K4: cfg_cal.h
A5: CAR_CFG_RADAR_CONFIG | B5: read | C5: OnChange | D5: 0 | E5: int32 | F5: 0 | G5: Radar configure 泊车雷达配置 | I5: Did0xf011 | J5: RADAR_CONFIG | K5: cfg_cal.h
A6: CAR_CFG_TRANSPARENT_CHASSIS | B6: read | C6: OnChange | D6: 0 | E6: int32 | F6: 0 | G6: 透明底盘 | I6: Did0xf011 | J6: TRANSPARENT_CHASSIS | K6: cfg_cal.h
A7: CAR_CFG_AUTOMATIC_PARKING_ASSIST | B7: read | C7: OnChange | D7: 0 | E7: int32 | F7: 0 | G7: 自动泊车辅助 | I7: Did0xf011 | J7: AUTOMATIC_PARKING_ASSIST | K7: cfg_cal.h
A8: CAR_CFG_RESERVED_1 | B8: read | C8: OnChange | D8: 0 | E8: int32 | F8: 0 | G8: RESERVED_ | I8: Did0xf011 | J8: RESERVED_1 | K8: cfg_cal.h
A9: CAR_CFG_ACC | B9: read | C9: OnChange | D9: 0 | E9: int32 | F9: 0 | G9: 启停式自适应智能巡航系统（ACC） | I9: Did0xf011 | J9: ACC | K9: cfg_cal.h
A10: CAR_CFG_TJA_ICA | B10: read | C10: OnChange | D10: 0 | E10: int32 | F10: 0 | G10: 智能巡航辅助 （TJA/ICA） | I10: Did0xf011 | J10: TJA_ICA | K10: cfg_cal.h
A11: CAR_CFG_SLKA | B11: read | C11: OnChange | D11: 0 | E11: int32 | F11: 0 | G11: 智慧礼让 （SLKA） | I11: Did0xf011 | J11: SLKA | K11: cfg_cal.h
A12: CAR_CFG_ASL | B12: read | C12: OnChange | D12: 0 | E12: int32 | F12: 0 | G12: 智能限速 （ASL） | I12: Did0xf011 | J12: ASL | K12: cfg_cal.h
A13: CAR_CFG_FCW | B13: read | C13: OnChange | D13: 0 | E13: int32 | F13: 0 | G13: 前碰撞预警 （FCW） | I13: Did0xf011 | J13: FCW | K13: cfg_cal.h
... A165: CAR_CFG_RESERVED_34 | B165: read | C165: OnChange | D165: 0 | E165: int32 | F165: 0 | G165: RESERVED_ | I165: Did0xf011 | J165: RESERVED_34 | K165: cfg_cal.h

Sheet vehicle.rx
A1: 属性名 | B1: 读写模式 | C1: 通知模式 | D1: 通知周期 | E1: 属性值类型 | F1: 默认值 | G1: 属性意义 | H1: CAN报文频率 （单位：ms） | I1: 事实高频 信号 | J1: 高频判断 备注 | K1: 使用进程 统计 | L1: WarnMsg04 | M1: 5/28版本信号OK？ | N1: 6/12版本信号OK? | O1: 6/14版本信号OK? | P1: 6/19版本信号OK? | Q1: 6/30版本信号OK? | R1: 6/13vehciledbg工具测试 | S1: 未测试原因？ | T1: QNX MW联调情况 | U1: 平台反馈 | V1: 是否是增程信号 | W1: 是否是纯电信号
A2: ADAS_AUDIOWARN_32C | B2: read | C2: OnChange | E2: int32 | F2: 0 | G2: ADAS声音报警ADAS_AudioWarn | H2: 20 | L2: 是 | M2: 是
A3: ADAS_FLTINDCR_340 | B3: read | C3: OnChange | E3: int32 | F3: 0 | G3: ADAS故障灯提示 ADAS_FltIndcr | H3: 20 | M3: 否 | N3: 否 | O3: 是 | R3: 否 | U3: 底层未支持 | V3: 是 | W3: 是
A4: ADAS_SPDLIM_ASL_347 | B4: read | C4: OnChange | E4: int32 | F4: 0 | G4: ASL智能限速速度ADAS_SpdLim_ASL | H4: 20 | M4: 否 | N4: 否 | O4: 是 | R4: 否 | U4: 底层未支持 | V4: 是 | W4: 是
A5: PDCUENRGMOD | B5: read | C5: OnChange | E5: int32 | F5: 0 | G5: ASL智能限速状态ADAS_SpdLimSts_ASL | H5: 20 | M5: 否 | N5: 否 | O5: 是 | R5: 否 | U5: 底层未支持 | V5: 是 | W5: 是
A6: ADAS_STS_AEB_33C | B6: read | C6: OnChange | E6: int32 | F6: 0 | G6: AEB状态ADAS_Sts_AEB | H6: 20 | M6: 否 | N6: 否 | O6: 是 | U6: 底层未支持 | V6: 是 | W6: 是
A7: ADAS_STS_FCW_33C | B7: read | C7: OnChange | E7: int32 | F7: 0 | G7: FCW状态ADAS_Sts_FCW | H7: 20 | M7: 否 | N7: 否 | O7: 是 | U7: 底层未支持 | V7: 是 | W7: 是
A8: BCM_FRNTHOODLIDSTS_343 | B8: read | C8: OnChange | E8: int32 | F8: 0 | G8: 前机舱盖状态BCM_FrntHoodLidSts | H8: 50 | L8: 是 | M8: 是
A9: BCM_HIBEAMOUTPCMD_335 | B9: read | C9: OnChange | E9: int32 | F9: 0 | G9: 远光指示灯BCM_HiBeamOutpCmd | H9: 50 | L9: 是 | M9: 是
A10: BCM_LEFRNTDOORSTS_343 | B10: read | C10: OnChange | E10: int32 | F10: 0 | G10: 左前门状态BCM_LeFrntDoorSts | H10: 50 | L10: 是 | M10: 是
A11: BCM_LEREDOORSTS_343 | B11: read | C11: OnChange | E11: int32 | F11: 0 | G11: 左后门状态BCM_LeReDoorSts | H11: 50 | L11: 是 | M11: 是
A12: BCM_LETRUNLAMPOUTPCMD_335 | B12: read | C12: OnChange | E12: int32 | F12: 0 | G12: 左转向指示灯BCM_LeTrunLampOutpCmd,0x0: Off,0x1: On | H12: 50 | L12: 是 | M12: 是
A13: BCM_LOBEAMOUTPCMD_335 | B13: read | C13: OnChange | E13: int32 | F13: 0 | G13: 近光指示灯BCM_LoBeamOutpCmd | H13: 50 | L13: 是 | M13: 是
A14: BCM_POSNLAMPOUTPCMD_335 | B14: read | C14: OnChange | E14: int32 | F14: 0 | G14: 位置灯信号BCM_PosnLampOutpCmd | H14: 50 | L14: 是 | M14: 是
A15: BCM_REFOGLAMPOUTPCMD_335 | B15: read | C15: OnChange | E15: int32 | F15: 0 | G15: 后雾灯信号BCM_ReFogLampOutpCmd | H15: 50 | L15: 是 | M15: 是
A16: BCM_RIFRNTDOORSTS_343 | B16: read | C16: OnChange | E16: int32 | F16: 0 | G16: 右前门状态BCM_RiFrntDoorSts | H16: 50 | L16: 是 | M16: 是
A17: BCM_RIREDOORSTS_343 | B17: read | C17: OnChange | E17: int32 | F17: 0 | G17: 右后门状态BCM_RiReDoorSts | H17: 50 | L17: 是 | M17: 是
A18: BCM_RITRUNLAMPOUTPCMD_335 | B18: read | C18: OnChange | E18: int32 | F18: 0 | G18: 右转向指示灯BCM_RiTrunLampOutpCmd,,0x0: Off,0x1: On | H18: 50 | L18: 是 | M18: 是
A19: BCM_TRSTS_343 | B19: read | C19: OnChange | E19: int32 | F19: 0 | G19: 后备箱状态BCM_TrSts | H19: 50 | L19: 是 | M19: 是
... A34: ESP_WARNINGON_261 | B34: read | C34: OnChange | E34: int32 | F34: 0 | G34: ESP制动故障点灯请求ESP_WarningOn | H34: 20 | L34: 是 | M34: 是
A35: MPC_FOBDSIGN_334 | B35: read | C35: OnChange | E35: int32 | F35: 0 | G35: 禁止类交通标志MPC_FobdSign | H35: 20 | M35: 否 | N35: 否 | O35: 是 | U35: 底层未支持 | V35: 是 | W35: 是
A36: MPC_OVERSPDWARN_SLA_32E | B36: read | C36: OnChange | E36: int32 | F36: 0 | G36: SLA超速报警MPC_OverSpdWarn_SLA | H36: 20 | M36: 否 | N36: 否 | O36: 是 | U36: 底层未支持 | V36: 是 | W36: 是
A37: MPC_OVERTAKESIGN_334 | B37: read | C37: OnChange | E37: int32 | F37: 0 | G37: 超车类交通标志MPC_OverTakeSign | H37: 20 | M37: 否 | N37: 否 | O37: 是 | U37: 底层未支持 | V37: 是 | W37: 是
A38: MPC_SPDLIM_SLA_32E | B38: read | C38: OnChange | E38: int32 | F38: 0 | G38: SLA限速MPC_SpdLim_SLA | H38: 20 | M38: 否 | N38: 否 | O38: 是 | U38: 底层未支持 | V38: 是 | W38: 是
A39: MPC_SPDLIMUNIT_SLA_32E | B39: read | C39: OnChange | E39: int32 | F39: 0 | G39: SLA限速单位MPC_SpdLimUnit_SLA | H39: 20 | M39: 否 | N39: 否 | O39: 是 | U39: 底层未支持 | V39: 是 | W39: 是
A40: MPC_STS_HMA_334 | B40: read | C40: OnChange | E40: int32 | F40: 0 | G40: HMA状态MPC_Sts_HMA | H40: 20 | M40: 否 | N40: 否 | O40: 是 | U40: 底层未支持 | V40: 是 | W40: 是
A41: MPC_WARNSIGN_334 | B41: read | C41: OnChange | E41: int32 | F41: 0 | G41: 警告类交通标志MPC_WarnSign | H41: 20 | M41: 否 | N41: 否 | O41: 是 | U41: 底层未支持 | V41: 是 | W41: 是
A42: VCU_CHRGDCHAGUNCNCTNINDCRLAMP_505 | B42: read | C42: OnChange | E42: int32 | F42: 0 | G42: 充放电枪连接指示灯PDCU_ChrgDchaGunCnctnIndcrLamp | H42: 100 | L42: 是 | M42: 否 | O42: 是 | U42: CarProperty未支持
A43: VCU_CHRGINDCRLAMP_505 | B43: read | C43: OnChange | E43: int32 | F43: 0 | G43: 充电提醒及充电状态指示灯VCU_ChrgIndcrLamp（纯电车型） 0x0: 灯灭 0x1: 灯亮 | H43: 100 | L43: 是 | M43: 是
A44: VCU_EGYRECOVFORBNFLG_505 | B44: read | C44: OnChange | E44: int32 | F44: 0 | G44: 能量回收功能禁止标志VCU_EgyRecovForbnFlg | H44: 100 | L44: 是 | M44: 是
A45: VCU_PWRBATTHVCNCTSTS_214 | B45: read | C45: OnChange | E45: int32 | F45: 0 | G45: 动力电池高压连接状态VCU_PwrBattHVCnctSts | H45: 10 | L45: 是 | M45: 是
A46: PEPS_PWRMOD_333 | B46: read | C46: OnChange | E46: int32 | F46: 0 | G46: 整车电源模式信号（前提PEPS_PWRMODVLD为0x1） 备注：N50/N51只有0x0/0x2/0x4这三种状态 0x0: off 0x1: acc(reserved) 0x2: ign on 0x3: crank pending(动力防盗认证过程中) 0x4: run 0x5: crank off(reserved) 0x6~-0x7: reserved | L46: 是 | M46: 是
A47: PEPS_PWRMODVLD_333 | B47: read | C47: OnChange | E47: int32 | F47: 0 | G47: 电源模式有效值 0x0: initializing 0x1: valid 0x2: invalid 0x3: reserved | L47: 是 | M47: 是
A48: PEPS_VCUAUTHENTFAILPROMT_37B | B48: read | C48: OnChange | E48: int32 | F48: 0 | G48: VCU认证失败提示PEPS_VCUAuthentFailPromt | H48: 100 | L48: 是 | M48: 是
A49: SDM_AIRBAGSYSALRMLAMPSTS_319 | B49: read | C49: OnChange | E49: int32 | F49: 0 | G49: 安全气囊系统报警灯SDM_AirBagSysAlrmLampSts | H49: 50 | L49: 是 | M49: 是
A50: SDM_DRVERSECUBLTALRMSTS_319 | B50: read | C50: OnChange | E50: int32 | F50: 0 | G50: 驾驶员安全带报警状态SDM_DrverSecuBltAlrmSts | H50: 50 | L50: 是 | M50: 是
A51: SDM_PASSSEATOCCSTS_319 | B51: read | C51: OnChange | E51: int32 | F51: 0 | G51: 乘客侧坐垫状态SDM_PassSeatOccSts | H51: 50 | L51: 是 | M51: 是
A52: SDM_PASSSECUBLTALRMSTS_319 | B52: read | C52: OnChange | E52: int32 | F52: 0 | G52: 副驾驶安全带报警状态SDM_PassSecuBltAlrmSts | H52: 50 | L52: 是 | M52: 否 | N52: 否 | O52: 是 | U52: 底层未支持 | V52: 是 | W52: 是
A53: SDM_SECUBLTALRMSTS_RL_319 | B53: read | C53: OnChange | E53: int32 | F53: 0 | G53: 后排左侧安全带报警状态SDM_SecuBltAlrmSts_RL | H53: 50 | L53: 是 | M53: 是
A54: SDM_SECUBLTALRMSTS_RM_319 | B54: read | C54: OnChange | E54: int32 | F54: 0 | G54: 后排中间安全带报警状态SDM_SecuBltAlrmSts_RM | H54: 50 | L54: 是 | M54: 是
...

Sheet vehicle_n8.rx
A1: 属性名 | B1: 读写模式 | C1: 通知模式 | D1: 通知周期 | E1: 属性值类型 | F1: 默认值 | G1: 属性意义 | H1: CAN报文频率 （单位：ms） | I1: 周立功自测结果
A2: BMS_CHRGSTSDISP_201 | B2: read | C2: OnChange | E2: int32 | F2: 0 | G2: 充电状态（显示） 0x0: 初始值 0x1: 充电准备中 0x2: 交流充电中（慢充中） 0x3: 无线充电中 0x4: 超级充电中 0x5: 直流充电中（快充中） 0x6: 交流充电预加热中 0x7: 无线充电预加热中 0x8: 直流充电预加热中 0x9: 交流充电保温中 0xA: 无线充电保温中 0xB: 直流充电保温中 0xC: 充电结束 0xD: 充电故障结束 0xE~0x1F: Reserved | H2: 50 | I2: ok
A3: BMS_VEH_DCHA_STA_201 | B3: read | C3: OnChange | E3: int32 | F3: 0 | G3: 车辆对外放电状态 0x0: 初始值 0x1: 放电准备中 0x2: 放电中 0x3: 放电结束 0x4: 车辆禁止放电 0x5~0x6: void 0x7: 无效值 | H3: 50 | I3: ok
A4: VCU_CHRGRESVSTSDISP_575 | B4: read | C4: OnChange | E4: int32 | F4: 0 | G4: 充电预约状态（显示） 0x0: 初始值 0x1: 预约充电 0x2: 定时出发 0x3~0x7: Reserved | H4: 100 | I4: ok
A5: VCU_CHRGDCHACRT_DISP_49C | B5: read | C5: OnChange | E5: int32 | F5: 0 | G5: 充放电电流(显示) 充电桩输出电流范围：0-1000A 单位：A | H5: 100 | I5: ok
A6: VCU_CHRGDCHAPWRDISP_49C | B6: read | C6: OnChange | E6: int32 | F6: 0 | G6: 充放电功率（显示） 范围为0-1000 单位：kW | H6: 100 | I6: ok
A7: BMS_CHGRESTIME_624 | B7: read | C7: OnChange | E7: int32 | F7: 0 | G7: 剩余充电时间(显示) 单位：min | H7: 1000 | I7: ok
A8: CHARGEFFICIENCY_FLAG_392 | B8: read | C8: OnChange | E8: int32 | F8: 0 | G8: 充电效率标志位 0x0: 初始值 0x1: 交流充电 0x2: 直流充电 0x3: Reservd | H8: 100 | I8: ok
A9: CHARGEFFICIENCY_392 | B9: read | C9: OnChange | E9: int32 | F9: 0 | G9: 充电效率（显示） 有效值：0~1000； 单位：kW/min | H9: 100 | I9: ok
A10: TIRESYSWARN_295 | B10: read | C10: OnChange | E10: int32 | F10: 0 | G10: 胎压系统故障 0x0: No any error 0x1: System error | H10: 500 | I10: ok
A11: TIRERIFRNTPWARN_295 | B11: read | C11: OnChange | E11: int32 | F11: 0 | G11: 右前轮胎状态 0x0: No warning. 0x1: High pressure warning. 0x2: Low pressure warning. 0x3: Quik leakage. 0x4: Lost Sensor 0x5: Sensor battery low 0x6: Sensor failure 0x7:Temperature warning | H11: 500 | I11: ng
A12: TIRELEFRNTPWARN_295 | B12: read | C12: OnChange | E12: int32 | F12: 0 | G12: 左前轮胎状态 0x0: No warning. 0x1: High pressure warning. 0x2: Low pressure warning. 0x3: Quik leakage. 0x4: Lost Sensor 0x5: Sensor battery low 0x6: Sensor failure 0x7:Temperature warning | H12: 500 | I12: ok
A13: TIRELEREPWARN_295 | B13: read | C13: OnChange | E13: int32 | F13: 0 | G13: 左后轮胎状态 0x0: No warning. 0x1: High pressure warning. 0x2: Low pressure warning. 0x3: Quik leakage. 0x4: Lost Sensor 0x5: Sensor battery low 0x6: Sensor failure 0x7:Temperature warning | H13: 500 | I13: ok
... A18: RIFRNTTIRET_295 | B18: read | C18: OnChange | E18: int32 | F18: 0 | G18: 右前轮胎温度 偏移量：-40 单位：℃ | H18: 500 | I18: ok
A19: LEFRNTP_295 | B19: read | C19: OnChange | E19: int32 | F19: 0 | G19: 左前轮胎压力 偏移量：-40 单位：℃ | H19: 500 | I19: ok | J19: 周立功无法发送，无法修改发送值
A20: RIFRNTP_295 | B20: read | C20: OnChange | E20: int32 | F20: 0 | G20: 右前轮胎压力 偏移量：-40 单位：℃ | H20: 500 | I20: ok | J20: 周立功无法发送，无法修改发送值
A21: RIREP_295 | B21: read | C21: OnChange | E21: int32 | F21: 0 | G21: 右后轮胎压力 偏移量：-40 单位：℃ | H21: 500 | I21: ok | J21: 周立功无法发送，无法修改发送值
A22: LEREP_295 | B22: read | C22: OnChange | E22: int32 | F22: 0 | G22: 左后轮胎压力 偏移量：-40 单位：℃ | H22: 500 | I22: ok | J22: 周立功无法发送，无法修改发送值
A23: SELRI_287 | B23: read | C23: OnChange | E23: int32 | F23: 0 | G23: 仪表循环翻页 0：inactive 1：active | I23: ok
A24: FRNTLETURNLIFAILRSTS_226 | B24: read | C24: OnChange | E24: int32 | F24: 0 | G24: 左前转向灯故障状态 0x0: no failure 0x1: failure | I24: ok
A25: RELETURNLIFAILRSTS_226 | B25: read | C25: OnChange | E25: int32 | F25: 0 | G25: 左后转向灯故障状态 0x0: no failure 0x1: failure | I25: ok
A26: FRNTRITURNLIFAILRSTS_226 | B26: read | C26: OnChange | E26: int32 | F26: 0 | G26: 右前转向灯故障状态 0x0: no failure 0x1: failure | I26: ok
A27: RERITURNLIFAILRSTS_226 | B27: read | C27: OnChange | E27: int32 | F27: 0 | G27: 右后转向灯故障状态 0x0: no failure 0x1: failure | I27: ok
A28: VCU_ANTITHEFTFAIL_56E | B28: read | C28: OnChange | E28: int32 | F28: 0 | G28: 动力防盗认证失败指示灯 0x1:点亮 0x0:熄灭 | I28: ok
A29: VCU_DRVR_PWR_LIM_LIG_631 | B29: read | C29: OnChange | E29: int32 | F29: 0 | G29: 驱动功率限制指示灯 0x1:点亮 0x0:熄灭 | I29: ok
A30: PBMPARKINGREMIND_1A7 | B30: read | C30: OnChange | E30: int32 | F30: 0 | G30: 驻车指示灯 0x1:点亮 0x0:熄灭 | I30: ok
A31: EMSENGSTS_3E4 | B31: read | C31: OnChange | E31: int32 | F31: 0 | G31: 发动机运行状态 0x0: Stand by 0x1: Ready 0x2: Cranking 0x3: Running 0x4: Stopping 0x5: Finish 0x6: AutoStopping 0x7: Reserved | I31: ok
A32: HMIMSGREQNR9_20D | B32: read | C32: OnChange | E32: int32 | F32: 0 | G32: 智能钥匙电量低 0x1: UID low battery 0x0: No Information | I32: ok
A33: HMIMSGREQNR7_20D | B33: read | C33: OnChange | E33: int32 | F33: 0 | G33: 智能钥匙遗忘车内 0x1: key in reminder 0x0: No Information | I33: ok
A34: HMIMSGREQNR3_20D | B34: read | C34: OnChange | E34: int32 | F34: 0 | G34: 请切换到D/R档启动 0x1: press bake to start 0x0: No Information | I34: ok
... A84: BMS_MONM_MIN_TEMP_ALARM_2E6 | B84: read | C84: OnChange | E84: int32 | F84: 0 | G84: 动力电池温度过低 0x1：有故障（仪表指示） 0x0:无故障（仪表不指示） | I84: ok
A85: ICMDISPVEHSPDVLD_1C5 | B85: read | C85: OnChange | E85: int32 | F85: 0 | G85: 仪表显示车速有效性标志位 0x0: Initializing(Reserved) 0x1: Valid 0x2: Invalid 0x3: Reserved | I85: ng | J85: TX信号
A86: ICMDISPVEHSPD_1C5 | B86: read | C86: OnChange | E86: int32 | F86: 0 | G86: 仪表显示车速 精度0.1 | I86: ng | J86: TX信号
A87: RMNMNTNMILG_59F | B87: read | C87: OnChange | E87: int32 | F87: 0 | G87: 保养里程 触发：RmnMntnMilg=0x0km 请立即保养 触发：超出保养里程0～10000km 请立即保养，已超出保养里程xx km 触发：保养里程超出大于10000km 请立即保养 报警解除：行驶里程小于5000KM | I87: ng | J87: 目前代码无使用需求
A88: FRNTLETURNLICMD_226 | B88: read | C88: OnChange | E88: int32 | F88: 0 | G88: 左前转向灯输出 0x0: Reserved 0x1: off 0x2: on 0x3: Invalid | I88: ok
A89: FRNTRITURNLICMD_226 | B89: read | C89: OnChange | E89: int32 | F89: 0 | G89: 右前转向灯输出 0x0: Reserved 0x1: off 0x2: on 0x3: Invalid | I89: ok
A90: VEHSPDVLD_185 | B90: read | C90: OnChange | E90: int32 | F90: 0 | G90: 仪表显示车速有效性标志位 0x0: Initializing 0x1: Valid 0x2: Invalid 0x3: Reserved | I90: ok
A91: OUTDT_3F2 | B91: read | C91: OnChange | E91: int32 | F91: 0 | G91: 车外温度 精度0.5 有效值：-40~70 | I91: ok
A92: MCUDRVMODSIG_127 | B92: read | C92: OnChange | E92: int32 | F92: 0 | G92: 驾驶模式信号 0x0: 初始值 0x1: 运动模式 0x2: 舒适模式 0x3: 经济模式 0x4: 雪地模式 0x5: 泥地模式 0x6: 沙地模式 0x7: One-Pedal模式 0x8: E-Auto模式 0x9: 狂暴模式 0xA: 赛道模式 0xB: 极致节能模式 0xC: 个性化模式 0xD: 晕车舒缓模式 0xE~0xF: Reserved | I92: ok
A93: MCUDRIRADICALDISPLAY_25F | B93: read | C93: OnChange | E93: int32 | F93: 0 | G93: 驾驶激进程度显示 0x0: 初始值； 0x1: 平和； 0x2: 正常； 0x3: 激进； | I93: ok
...

Sheet psis.usr_cfg
A1: 属性名 | B1: 读写模式 | C1: 通知模式 | D1: 通知周期 | E1: 属性值类型 | F1: 默认值 | G1: 属性意义 | H1: 属性值长度 | I1: 恢复出厂设置是否重置 | J1: ModuleName
A2: USR_LANGUAGE_SETTING | B2: read&write | C2: OnChange | E2: int32 | F2: 0 | G2: 语言设置： 0：汉语 1：英语 | H2: 4 | I2: N | J2: clusterapp_usr
A3: USR_DAYNIGHT_MODE | B3: read&write | C3: OnChange | E3: int32 | F3: 0 | G3: 白天黑夜模式 0：白天 1：黑夜 | H3: 4 | I3: N | J3: clusterapp_usr
A4: USR_EXTERNAL_APP_ACTIVE_CODE | B4: read&write | C4: OnChange | E4: bytes | F4: 0 | G4: 第三方APP生态激活码 | H4: 32 | I4: N | J4: clusterapp_usr
A5: USR_BATTERY_LEVEL_UNIT | B5: read&write | C5: OnChange | E5: int32 | F5: 0 | G5: 增程车电量续航和百分比显示切换： 0：显示km 1：显示百分比 | H5: 4 | I5: N | J5: clusterapp_usr
A6: USR_TIME_FORMAT | B6: read&write | C6: OnChange | E6: int32 | F6: 0 | G6: 时间制式 - 休眠保存 0: 24小时 1: 12小时 | H6: 4 | I6: N | J6: clusterapp_usr
A7: USR_HUD_BSD_SWITCH | B7: read&write | C7: OnChange | E7: int32 | F7: 1 | G7: HUD显示盲区影像开关： 0：关闭 1：开启 2：置灰 | H7: 4 | I7: N | J7: clusterapp_usr | K7: 恢复中控出厂设置时需要恢复默认
A8: USR_HUD_SWITCH | B8: read&write | C8: OnChange | E8: int32 | F8: 1 | G8: WHUD开关状态： 0：关闭 1：开启 | H8: 4 | I8: N | J8: clusterapp_usr
A9: USR_HUD_HEIADJ | B9: read&write | C9: OnChange | E9: int32 | F9: 5 | G9: WHUD高度档位值： 0x1: Level1 0x2: Level2 0x3: Level3 0x4: Level4 0x5: Level5 0x6: Level6 0x7: Level7 0x8: Level8 0x9: Level9 0xA: Level10 | H9: 4 | I9: N | J9: clusterapp_usr
A10: USR_HUD_ILLADJ | B10: read&write | C10: OnChange | E10: int32 | F10: 5 | G10: WHUD亮度档位值： 0x1: Level1 0x2: Level2 0x3: Level3 0x4: Level4 0x5: Level5 0x6: Level6 0x7: Level7 0x8: Level8 0x9: Level9 0xA: Level10 | H10: 4 | I10: N | J10: clusterapp_usr
A11: USR_HUD_MODSWT | B11: read&write | C11: OnChange | E11: int32 | F11: 1 | G11: WHUD主题模式： 0x1: 全显模式 0x2: 运动模式 0x3: 精简模式 | H11: 4 | I11: N | J11: clusterapp_usr
A12: USR_HUD_SNOWMODESWTSTS | B12: read&write | C12: OnChange | E12: int32 | F12: 1 | G12: WHUD色彩模式： 0x1: Off 0x2: On | H12: 4 | I12: N | J12: clusterapp_usr
A13: USR_HUD_CRTLANGUAGE | B13: read&write | C13: OnChange | E13: int32 | F13: 0 | G13: WHUD语言种类： 0x0: Chinese 0x1: English | H13: 4 | I13: N | J13: clusterapp_usr
A14: USR_HMI_PAGEINDEX | B14: read&write | C14: OnChange | E14: int32 | F14: 2 | G14: 0-电话 1-导航 2-多媒体 3-胎压 4-总里程 5-本次里程 | H14: 4 | I14: Y | J14: clusterapp_usr
A15: USR_DISTANCE_SPEED_UNIT_SWITCH | B15: read&write | C15: OnChange | E15: int32 | F15: 0 | G15: 里程和速度单位开关： 0：公里、公里/时 1：英里、英里/时 | H15: 4 | I15: N | J15: clusterapp_usr
A16: USR_WARN_VOLUME_LEVEL | B16: read&write | C16: OnChange | E16: int32 | F16: 1 | G16: 音量等级： 0：低 1：中 2：高 | H16: 4 | I16: N | J16: clusterapp_usr
A17: USR_DISPLAY_BRIGHTNESS_LEVEL | B17: read&write | C17: OnChange | E17: bytes | F17: 0 | G17: 各个显示屏亮度 value:1~100 | H17: 64 | I17: Y | J17: clusterapp_usr
A18: USR_ADAS_SWITCH | B18: read&write | C18: OnChange | E18: int32 | F18: 0 | G18: ADAS开关状态： 0：关闭 1：开启 | H18: 4 | I18: N | J18: clusterapp_usr
A19: USR_SEC_THI_FASTEN_SWITCH | B19: read&write | C19: OnChange | E19: int32 | F19: 1 | G19: 二排、三排安全带提示声播放开关 0 ： 关闭 1 ：开启（默认） | H19: 4 | I19: N | J19: clusterapp_usr
... A32: USR_AVAS_STATUS | B32: read&write | C32: OnChange | E32: int32 | F32: 0 | G32: 行人警示音： 0：关闭 1：声音1 2：声音2 （暂时只关注0） | H32: 4 | I32: N | J32: clusterapp_usr

Sheet ivi.rx
A1: 属性名 | B1: 读写模式 | C1: 通知模式 | D1: 通知周期 | E1: 属性值类型 | F1: 默认值 | G1: 属性意义
A2: I2C_DAYNIGHT_MODE | B2: read | C2: OnChange | E2: int32 | F2: 0 | G2: 白天黑夜模式
A3: I2C_LANGUAGE_SETTING | B3: read | C3: OnChange | E3: int32 | F3: 0 | G3: 语言设置： 0：汉语 1：英语
A4: I2C_STARTUP_STS | B4: read | C4: OnEvent | E4: int32 | F4: 0 | G4: IVI Interaction 具备通信能力（fwk与midware通信建立），注：不代表 IVI 具备控屏能力 0: 中控启动未完成 1: 中控启动完成
A5: I2C_DISPLAY_STS | B5: read | C5: OnChange | E5: int32 | F5: 0 | G5: IVI 控屏能力状态（app显示） 0: 中控尚未具备中控屏的显示能力 1: 中控具备中控屏的显示能力
A6: I2C_FACTORY_RESET | B6: read | C6: OnEvent | E6: int32 | F6: 0 | G6: 中控界面上恢复出厂后发出通知： 1：仪表恢复出厂； 2：中控恢复出厂; 3: 全部恢复出厂设置
A7: I2C_FULL_SCREEN | B7: read | C7: OnChange | E7: int32 | F7: 0 | G7: IVI通知仪表全屏显示: 0：非全屏 1：全屏
A8: I2C_BATTERY_LEVEL_UNIT | B8: read | C8: OnChange | E8: int32 | F8: 0 | G8: 增程车电量续航和百分比显示切换： 0：显示km 1：显示百分比
A9: I2C_TIME_FORMAT | B9: read | C9: OnChange | E9: int32 | F9: 0 | G9: 时间制式 - 休眠保存 0: 24小时 1: 12小时
A10: I2C_WARN_VOLUME_LEVEL | B10: read | C10: OnChange | E10: int32 | F10: 1 | G10: 音量等级： 0：低 1：中 2：高
A11: D:\download\BAIC-55947\AL\slog2\dlog\data0\binlog-bsp-192.168.1.101\BSPLOG | B11: read | C11: OnChange | E11: int32 | F11: 0 | G11: ESE模拟声浪开关： 0：关 1：开 | H11: 透传给AVAS，不需要QNX记忆
A12: I2C_ESE_VOLUME_LEVEL | B12: read | C12: OnChange | E12: int32 | F12: 22 | G12: ESE模拟声浪音量等级：0~30 0:静音 1~30:音量大小1~30 | H12: 透传给AVAS，不需要QNX记忆
A13: I2C_ESE_MODE | B13: read | C13: OnChange | E13: int32 | F13: 0 | G13: ESE模拟声浪类型： 0：v8引擎 1：v12引擎 2：转子引擎 3：电子声浪 | H13: 透传给AVAS，不需要QNX记忆
A14: I2C_AVAS_STATUS | B14: read | C14: OnChange | E14: int32 | F14: 0 | G14: 行人警示音： 0：关闭 1：声音1 2：声音2 （暂时只关注0） | H14: 透传给AVAS，不需要QNX记忆
A15: I2C_HUD_BSD_SWITCH | B15: read | C15: OnChange | E15: int32 | F15: 1 | G15: HUD显示盲区影像开关： 0：关闭 1：开启
A16: I2C_NAVI_GUIDE_INFO | B16: read | C16: OnChange | E16: string | F16: "" | G16: IVI发布导航引导信息-WHUD
A17: I2C_CALL_CONTACT_INFO | B17: read | C17: OnChange | E17: string | F17: "" | G17: IVI发布通话信息-WHUD
A18: I2C_NAVI_LANE_INFO | B18: read | C18: OnChange | E18: string | F18: "" | G18: IVI发布车道线信息-WHUD
A19: I2C_TMC_SEGMENT_INFO | B19: read | C19: OnChange | E19: string | F19: "" | G19: IVI发布光柱图信息-WHUD
A20: I2C_TRAFFIC_LIGHT_INFO | B20: read | C20: OnChange | E20: string | F20: "" | G20: IVI发布红绿灯信息-WHUD
A21: I2C_CLUSTER_SOUND_TEST | B21: read | C21: OnEvent | E21: int32 | F21: 0 | G21: 工程模式仪表扬声器测试： 0：停止 1：播放
A22: I2C_SMART_KEY_SWITCH | B22: read | C22: OnChange | E22: int32 | F22: 0 | G22: 智能开启后备箱开关状态： 0：invalid 1：close 2：open
A23: I2C_SOFTWARE_VERSION | B23: read | C23: OnChange | E23: string | F23: "" | G23: 软件版本号，例如： v1.0.4-alpha115-step2_20250701
A24: I2C_HUD_HOMETHEATRE | B24: read | C24: OnEvent | E24: int32 | F24: 0 | G24: HUD家庭影院状态 0：退出家庭影院状态 1：进入家庭影院状态
A25: I2C_NTC_TEMP_HIGH_LIGHT_DOWN | B25: read | C25: OnChange | E25: int32 | F25: 0 | G25: NTC温度85°C~95°C 报警文言：屏幕温度过高，已自动降低亮度 0：无此报警或此报警消失 1：触发此报警
A26: I2C_NTC_TEMP_HIGH_OFF_SCREEN | B26: read | C26: OnChange | E26: int32 | F26: 0 | G26: NTC温度95°C以上 报警文言：屏幕温度过高，5s后关闭，降温自动恢复 0：无此报警或此报警消失 1：触发此报警
A27: I2C_NAVI_STATUS | B27: read | C27: OnChange | E27: int32 | F27: 0 | G27: 中控导航状态： 0：导航关闭 1：导航开启
A28: I2C_CALL_STATUS | B28: read | C28: OnChange | E28: int32 | F28: 0 | G28: 中控蓝牙电话状态： 0：未在通话 1：正在通话
A29: I2C_LOG_EXPORT_STATUS | B29: read | C29: OnChange | E29: int32 | F29: 0 | G29: 0：当前未导出log 1：开始导出log
A30: I2C_TRUNK_DISABLE_CLICKED | B30: read | C30: OnEvent | E30: int32 | F30: 0 | G30: 后备箱按钮置灰状态点击事件： 0：未点击 1：点击
A31: I2C_QNX_SCREENSHOT | B31: read | C31: OnEvent | E31: int32 | F31: 0 | G31: 通知仪表截屏 0：默认 1：截屏
A32: I2C_AVM_ALARM_SWITCH | B32: read | C32: OnChange | E32: int32 | F32: 1 | G32: AVM雷达报警音开关 0：关闭 1：开启（默认）
A33: I2C_DISTANCE_SPEED_UNIT_SWITCH | B33: read | C33: OnChange | E33: int32 | F33: 0 | G33: 里程和速度单位开关： 0：公里、公里/时 1：英里、英里/时
A34: I2C_AVM_STATUS | B34: read | C34: OnChange | E34: int32 | F34: 0 | G34: AVM状态： 0：关闭 1：打开
A35: I2C_HUD_BSD_STATUS | B35: read | C35: OnChange | E35: int32 | F35: 0 | G35: HUD盲区影像状态： 0：不显示影像 1：显示左侧影像 2：显示右侧影像
... A58: I2C_DMS_CAMERA_OCCLUSION_INTERVAL | B58: read | C58: OnEvent | E58: int32 | F58: 0 | G58: DMS摄像头遮挡监测提醒间隔 单位：分钟 有效值：>0
A59: I2C_DMS_ACTIVATION_DATA | B59: read | C59: OnEvent | E59: string | F59: "" | G59: DMS激活授权码
A60: I2C_BATTERY_CHARGE_LIMIT | B60: read | C60: OnEvent | E60: int32 | F60: 0 | G60: 充电限值百分比，取值范围 60~100
A61: I2C_REAR_SPOILER_STS | B61: read | C61: OnChange | E61: int32 | F61: 0 | G61: 电动尾翼开启状态， 0：关闭 1：开启 2：自动
A62: I2C_STEERING_WHEEL_HEAT_FLT | B62: read | C62: OnChange | E62: int32 | F62: 0 | G62: 方向盘加热故障， 0：无故障 1：故障
...

Sheet ivi.tx
A1: 属性名 | B1: 读写模式 | C1: 通知模式 | D1: 通知周期 | E1: 属性值类型 | F1: 默认值 | G1: 属性意义
A2: C2I_WARN_HISTORY_LIST_STR | B2: read&write | C2: OnChange | E2: array | F2: [ , , ] | G2: 历史报警列表 0： 当前无历史报警 非0，按照excel 表对照id与报警进行显示
A3: C2I_SOC_VERSION | B3: read&write | C3: OnEvent | E3: string | F3: "" | G3: SOC的版本
A4: C2I_DAYNIGHT_MODE | B4: read&write | C4: OnEvent | E4: int32 | F4: 0 | G4: 白天黑夜模式 | H4: 中控启动后需回传记忆
A5: C2I_LANGUAGE_SETTING | B5: read&write | C5: OnEvent | E5: int32 | F5: 0 | G5: 语言设置： 0：汉语 1：英语 | H5: 中控启动后需回传记忆
A6: C2I_CHARGE_CENTER_REQUEST | B6: read&write | C6: OnEvent | E6: int32 | F6: 0 | G6: 0：默认值无操作；1:打开中控能量管理中心
A7: C2I_MIRRCMD_DIS | B7: read&write | C7: OnEvent | E7: int32 | F7: 0 | G7: 0：默认值无操作；1:打开后视镜调节
